<?xml version="1.0" encoding="utf-8"?>
<robot name="ModularBot">
  <material name="blue">
    <color rgba="0 0 0.8 1"/>
  </material>
  <material name="black">
    <color rgba="0 0 0 1"/>
  </material>
  <material name="white">
    <color rgba="1 1 1 1"/>
  </material>
  <material name="grey">
    <color rgba="0.5 0.5 0.5 1"/>
  </material>
  <material name="red">
    <color rgba="1 0 0 1"/>
  </material>
  <material name="green">
    <color rgba="0 1 0 1"/>
  </material>
  <material name="yellow">
    <color rgba="1 1 0 1"/>
  </material>
  <material name="tree_green">
    <color rgba="0.13 0.54 0.13 1"/>
  </material>
  <origin rpy="0 0 0" xyz="0.0 0.0 0.8"/>
  <link name="base_link">
    <inertial>
      <mass value="0.001"/>
      <inertia ixx="1.0e-06" ixy="0.0" ixz="0.0" iyy="1.0e-06" iyz="0.0" izz="1.0e-06"/>
    </inertial>
  </link>
  <gazebo>
    <plugin filename="libxbot2_gz_joint_server.so" name="xbot2_gz_joint_server">
      <pid>
        <gain d="10" name="small_mot" p="100"/>
        <gain d="50" name="medium_mot" p="500"/>
        <gain d="100" name="big_mot" p="1000"/>
        <gain name="J1_A" profile="medium_mot"/>
        <gain d="50" name="J_wheel_A" p="0"/>
        <gain name="J1_B" profile="medium_mot"/>
        <gain d="50" name="J_wheel_B" p="0"/>
        <gain name="J1_C" profile="medium_mot"/>
        <gain d="50" name="J_wheel_C" p="0"/>
        <gain name="J1_D" profile="medium_mot"/>
        <gain d="50" name="J_wheel_D" p="0"/>
        <gain name="J1_E" profile="small_mot"/>
        <gain name="J2_E" profile="medium_mot"/>
        <gain name="J3_E" profile="small_mot"/>
        <gain name="J4_E" profile="medium_mot"/>
        <gain name="J5_E" profile="small_mot"/>
        <gain name="J6_E" profile="medium_mot"/>
      </pid>
    </plugin>
  </gazebo>
  <joint name="fixed" type="fixed">
    <parent link="base_link"/>
    <child link="mobile_base"/>
    <axis rpy="0 0 0" xyz="0 0 1"/>
    <origin rpy="0.0 0.0 0.0" xyz="0.0 0.0 0.0"/>
  </joint>
  <link name="mobile_base">
    <visual>
      <origin rpy="0.0 -0.0 0.0" xyz="0 0 0"/>
      <geometry>
        <mesh filename="package://concert_resources/models/modular/meshes/concert/concert_central_body.stl" scale="0.001 0.001 0.001"/>
      </geometry>
    </visual>
    <collision>
      <origin rpy="0.0 -0.0 0.0" xyz="0 0 0"/>
      <geometry>
        <mesh filename="package://concert_resources/models/modular/meshes/concert/simple/concert_central_body.stl" scale="0.001 0.001 0.001"/>
      </geometry>
    </collision>
    <inertial>
      <origin rpy="0 0 0" xyz="0.012213513 0.0 -0.21761073"/>
      <mass value="127.57599"/>
      <inertia ixx="19.025397" ixy="-0.62823044" ixz="-0.064261485" iyy="13.251602" iyz="0.91864796" izz="23.575473"/>
    </inertial>
  </link>
  <!-- camera body, with origin at bottom screw mount -->
  <joint name="D435i_camera_front_joint" type="fixed">
    <origin rpy="0 0.261799 0" xyz="0.402872 0.0 -0.078218"/>
    <parent link="mobile_base"/>
    <child link="D435i_camera_front_bottom_screw_frame"/>
  </joint>
  <link name="D435i_camera_front_bottom_screw_frame"/>
  <!-- camera body, with origin at bottom screw mount -->
  <joint name="D435i_camera_back_joint" type="fixed">
    <origin rpy="0 0.261799 3.141593" xyz="-0.402872 0.0 -0.078218"/>
    <parent link="mobile_base"/>
    <child link="D435i_camera_back_bottom_screw_frame"/>
  </joint>
  <link name="D435i_camera_back_bottom_screw_frame"/>
  <!-- camera body, with origin at bottom screw mount -->
  <joint name="T265_camera_left_joint" type="fixed">
    <origin rpy="3.141593 0.0 1.570796" xyz="0.02375 0.37245 -0.062"/>
    <parent link="mobile_base"/>
    <child link="T265_camera_left_pose_frame"/>
  </joint>
  <link name="T265_camera_left_pose_frame"/>
  <!-- camera body, with origin at bottom screw mount -->
  <joint name="T265_camera_right_joint" type="fixed">
    <origin rpy="0 0.0 -1.570796" xyz="0.02375 -0.37245 -0.062"/>
    <parent link="mobile_base"/>
    <child link="T265_camera_right_pose_frame"/>
  </joint>
  <link name="T265_camera_right_pose_frame"/>
  <!-- camera body, with origin at bottom screw mount -->
  <joint name="front_base_base_mount_joint" type="fixed">
    <origin rpy="0.0 0.0 0.0" xyz="0.5305 0.315 -0.1"/>
    <parent link="mobile_base"/>
    <child link="front_base_base_link"/>
  </joint>
  <link name="front_base_base_link"/>
  <joint name="back_base_base_mount_joint" type="fixed">
    <origin rpy="0.0 0.0 3.141593" xyz="-0.5305 -0.315 -0.1"/>
    <parent link="mobile_base"/>
    <child link="back_base_base_link"/>
  </joint>
  <link name="back_base_base_link"/>
  <joint name="ultrasound_fl_sag_base_mount_joint" type="fixed">
    <origin rpy="0.0 1.963496 0.0" xyz="0.5105 0.315 -0.129"/>
    <parent link="mobile_base"/>
    <child link="ultrasound_fl_sag_base_link"/>
  </joint>
  <link name="ultrasound_fl_sag_base_link"/>
  <!-- Rotate sensor frame (readings are on x axis instead of z) -->
  <joint name="ultrasound_fl_sag_joint" type="fixed">
    <origin rpy="0.0 -1.57 0.0" xyz="0 0 0"/>
    <parent link="ultrasound_fl_sag_base_link"/>
    <child link="ultrasound_fl_sag"/>
  </joint>
  <link name="ultrasound_fl_sag"/>
  <joint name="ultrasound_fr_sag_base_mount_joint" type="fixed">
    <origin rpy="0.0 1.963496 0.0" xyz="0.5105 -0.315 -0.129"/>
    <parent link="mobile_base"/>
    <child link="ultrasound_fr_sag_base_link"/>
  </joint>
  <link name="ultrasound_fr_sag_base_link"/>
  <!-- Rotate sensor frame (readings are on x axis instead of z) -->
  <joint name="ultrasound_fr_sag_joint" type="fixed">
    <origin rpy="0.0 -1.57 0.0" xyz="0 0 0"/>
    <parent link="ultrasound_fr_sag_base_link"/>
    <child link="ultrasound_fr_sag"/>
  </joint>
  <link name="ultrasound_fr_sag"/>
  <joint name="ultrasound_rl_sag_base_mount_joint" type="fixed">
    <origin rpy="0.0 1.963496 3.141593" xyz="-0.5105 0.315 -0.129"/>
    <parent link="mobile_base"/>
    <child link="ultrasound_rl_sag_base_link"/>
  </joint>
  <link name="ultrasound_rl_sag_base_link"/>
  <!-- Rotate sensor frame (readings are on x axis instead of z) -->
  <joint name="ultrasound_rl_sag_joint" type="fixed">
    <origin rpy="0.0 -1.57 0.0" xyz="0 0 0"/>
    <parent link="ultrasound_rl_sag_base_link"/>
    <child link="ultrasound_rl_sag"/>
  </joint>
  <link name="ultrasound_rl_sag"/>
  <joint name="ultrasound_rr_sag_base_mount_joint" type="fixed">
    <origin rpy="0.0 1.963496 3.141593" xyz="-0.5105 -0.315 -0.129"/>
    <parent link="mobile_base"/>
    <child link="ultrasound_rr_sag_base_link"/>
  </joint>
  <link name="ultrasound_rr_sag_base_link"/>
  <!-- Rotate sensor frame (readings are on x axis instead of z) -->
  <joint name="ultrasound_rr_sag_joint" type="fixed">
    <origin rpy="0.0 -1.57 0.0" xyz="0 0 0"/>
    <parent link="ultrasound_rr_sag_base_link"/>
    <child link="ultrasound_rr_sag"/>
  </joint>
  <link name="ultrasound_rr_sag"/>
  <joint name="ultrasound_fl_lat_base_mount_joint" type="fixed">
    <origin rpy="0.0 1.963496 1.570796" xyz="0.4515 0.365 -0.117"/>
    <parent link="mobile_base"/>
    <child link="ultrasound_fl_lat_base_link"/>
  </joint>
  <link name="ultrasound_fl_lat_base_link"/>
  <!-- Rotate sensor frame (readings are on x axis instead of z) -->
  <joint name="ultrasound_fl_lat_joint" type="fixed">
    <origin rpy="0.0 -1.57 0.0" xyz="0 0 0"/>
    <parent link="ultrasound_fl_lat_base_link"/>
    <child link="ultrasound_fl_lat"/>
  </joint>
  <link name="ultrasound_fl_lat"/>
  <joint name="ultrasound_rl_lat_base_mount_joint" type="fixed">
    <origin rpy="0.0 1.963496 1.570796" xyz="-0.4515 0.365 -0.117"/>
    <parent link="mobile_base"/>
    <child link="ultrasound_rl_lat_base_link"/>
  </joint>
  <link name="ultrasound_rl_lat_base_link"/>
  <!-- Rotate sensor frame (readings are on x axis instead of z) -->
  <joint name="ultrasound_rl_lat_joint" type="fixed">
    <origin rpy="0.0 -1.57 0.0" xyz="0 0 0"/>
    <parent link="ultrasound_rl_lat_base_link"/>
    <child link="ultrasound_rl_lat"/>
  </joint>
  <link name="ultrasound_rl_lat"/>
  <joint name="ultrasound_fr_lat_base_mount_joint" type="fixed">
    <origin rpy="0.0 1.963496 -1.570796" xyz="0.4515 -0.365 -0.117"/>
    <parent link="mobile_base"/>
    <child link="ultrasound_fr_lat_base_link"/>
  </joint>
  <link name="ultrasound_fr_lat_base_link"/>
  <!-- Rotate sensor frame (readings are on x axis instead of z) -->
  <joint name="ultrasound_fr_lat_joint" type="fixed">
    <origin rpy="0.0 -1.57 0.0" xyz="0 0 0"/>
    <parent link="ultrasound_fr_lat_base_link"/>
    <child link="ultrasound_fr_lat"/>
  </joint>
  <link name="ultrasound_fr_lat"/>
  <joint name="ultrasound_rr_lat_base_mount_joint" type="fixed">
    <origin rpy="0.0 1.963496 -1.570796" xyz="-0.4515 -0.365 -0.117"/>
    <parent link="mobile_base"/>
    <child link="ultrasound_rr_lat_base_link"/>
  </joint>
  <link name="ultrasound_rr_lat_base_link"/>
  <!-- Rotate sensor frame (readings are on x axis instead of z) -->
  <joint name="ultrasound_rr_lat_joint" type="fixed">
    <origin rpy="0.0 -1.57 0.0" xyz="0 0 0"/>
    <parent link="ultrasound_rr_lat_base_link"/>
    <child link="ultrasound_rr_lat"/>
  </joint>
  <link name="ultrasound_rr_lat"/>
  <gazebo reference="mobile_base">
    <mu1>0.2</mu1>
    <mu2>0.2</mu2>
    <kp>100000000.0</kp>
    <kd>1.0</kd>
    <maxVel>0.0</maxVel>
    <minDepth>0.0001</minDepth>
    <material>Gazebo/Grey</material>
    <selfCollide>True</selfCollide>
  </gazebo>
  <joint name="fixed_J1_A" type="fixed">
    <axis rpy="0 0 0" xyz="0 0 1"/>
    <parent link="mobile_base"/>
    <child link="J1_A_stator"/>
    <origin rpy="-3.141592653589793 -1.5707963267948966 0.0" xyz="0.37925 0.3125 -0.195"/>
  </joint>
  <link name="J1_A_stator">
    <visual>
      <origin rpy="0.0 -0.0 0.0" xyz="0 0 0"/>
      <geometry>
        <mesh filename="package://concert_resources/models/modular/meshes/concert/concert_steering_connection_module.stl" scale="0.001 0.001 0.001"/>
      </geometry>
    </visual>
    <collision>
      <origin rpy="0.0 -0.0 0.0" xyz="0 0 0"/>
      <geometry>
        <mesh filename="package://concert_resources/models/modular/meshes/concert/simple/concert_steering_connection_module.stl" scale="0.001 0.001 0.001"/>
      </geometry>
    </collision>
    <inertial>
      <origin rpy="0 0 0" xyz="-0.0079406061 0.0 0.037039629"/>
      <mass value="1.1813661"/>
      <inertia ixx="0.0026106263" ixy="0.0" ixz="0.00017928188" iyy="0.0027438806" iyz="0.0" izz="0.0025223123"/>
    </inertial>
  </link>
  <gazebo reference="J1_A_stator">
    <mu1>0.2</mu1>
    <mu2>0.2</mu2>
    <kp>100000000.0</kp>
    <kd>1.0</kd>
    <maxVel>0.0</maxVel>
    <minDepth>0.0001</minDepth>
    <material>Gazebo/Blue</material>
    <selfCollide>True</selfCollide>
  </gazebo>
  <joint name="J1_A" type="revolute">
    <axis rpy="0 0 0" xyz="0 0 1"/>
    <parent link="J1_A_stator"/>
    <child link="L_1_A"/>
    <origin rpy="-1.5707963267948966 -0.0 1.5707963267948966" xyz="-0.022 0.0 0.06075"/>
    <limit effort="127.0" lower="-2.6" upper="2.6" velocity="8.1"/>
  </joint>
  <link name="L_1_A">
    <visual>
      <origin rpy="3.141592653589793 -0.0 0.0" xyz="0 0 0"/>
      <geometry>
        <mesh filename="package://concert_resources/models/modular/meshes/concert/concert_steering_module_frame.stl" scale="0.001 0.001 0.001"/>
      </geometry>
    </visual>
    <collision>
      <origin rpy="3.141592653589793 -0.0 0.0" xyz="0 0 0"/>
      <geometry>
        <mesh filename="package://concert_resources/models/modular/meshes/concert/simple/concert_steering_module_frame.stl" scale="0.001 0.001 0.001"/>
      </geometry>
    </collision>
    <inertial>
      <origin rpy="0 0 0" xyz="0.090718433 0.0 0.22670598"/>
      <mass value="7.6995028"/>
      <inertia ixx="0.44048889" ixy="-0.03668535" ixz="0.025595962" iyy="0.52073797" iyz="-0.0026667139" izz="0.69985532"/>
    </inertial>
  </link>
  <gazebo reference="L_1_A">
    <mu1>0.2</mu1>
    <mu2>0.2</mu2>
    <kp>100000000.0</kp>
    <kd>1.0</kd>
    <maxVel>0.0</maxVel>
    <minDepth>0.0001</minDepth>
    <material>Gazebo/White</material>
    <selfCollide>True</selfCollide>
  </gazebo>
  <joint name="fixed_J_wheel_A" type="fixed">
    <axis rpy="0 0 0" xyz="0 0 1"/>
    <parent link="L_1_A"/>
    <child link="J_wheel_A_stator"/>
    <origin rpy="-3.141592653589793 1.5707963267948966 0.0" xyz="0.0 0.0 0.37015"/>
  </joint>
  <link name="J_wheel_A_stator">
    <inertial>
      <mass value="0.001"/>
      <inertia ixx="1.0e-06" ixy="0.0" ixz="0.0" iyy="1.0e-06" iyz="0.0" izz="1.0e-06"/>
    </inertial>
  </link>
  <gazebo reference="J_wheel_A_stator"/>
  <joint name="J_wheel_A" type="revolute">
    <axis rpy="0 0 0" xyz="0 0 1"/>
    <parent link="J_wheel_A_stator"/>
    <child link="wheel_A"/>
    <origin rpy="0.0 -0.0 0.0" xyz="0.0 0.0 0.0"/>
    <limit effort="24.0" lower="-10000000000.0" upper="10000000000.0" velocity="9.5"/>
  </joint>
  <link name="wheel_A">
    <visual>
      <origin rpy="0.0 -0.0 0.0" xyz="0 0 0"/>
      <geometry>
        <mesh filename="package://concert_resources/models/modular/meshes/concert/concert_wheel.stl" scale="0.001 0.001 0.001"/>
      </geometry>
    </visual>
    <collision>
      <origin rpy="0.0 -0.0 0.0" xyz="0 0 0"/>
      <geometry>
        <cylinder length="0.1" radius="0.16"/>
      </geometry>
    </collision>
    <inertial>
      <origin rpy="0 0 0" xyz="0.0 0.0 -0.005"/>
      <mass value="4.0116207"/>
      <inertia ixx="0.028580559" ixy="0.0" ixz="0.0" iyy="0.028580559" iyz="0.0" izz="0.044954065"/>
    </inertial>
  </link>
  <gazebo reference="wheel_A">
    <material>Gazebo/Residential</material>
    <selfCollide>True</selfCollide>
    <collision>
      <surface>
        <friction>
          <ode>
            <mu>1.0</mu>
            <mu2>1.0</mu2>
          </ode>
          <bullet>
            <friction>1.0</friction>
            <friction2>1.0</friction2>
          </bullet>
        </friction>
        <contact>
          <ode>
            <kp>2100000</kp>
            <kd>1</kd>
            <max_vel>100</max_vel>
          </ode>
          <bullet>
            <soft_cfm>0.007</soft_cfm>
            <soft_erp>0.25</soft_erp>
            <kp>1000000</kp>
            <kd>5</kd>
          </bullet>
        </contact>
      </surface>
    </collision>
  </gazebo>
  <joint name="fixed_J1_B" type="fixed">
    <axis rpy="0 0 0" xyz="0 0 1"/>
    <parent link="mobile_base"/>
    <child link="J1_B_stator"/>
    <origin rpy="-3.141592653589793 -1.5707963267948966 0.0" xyz="0.37925 -0.3125 -0.195"/>
  </joint>
  <link name="J1_B_stator">
    <visual>
      <origin rpy="0.0 -0.0 0.0" xyz="0 0 0"/>
      <geometry>
        <mesh filename="package://concert_resources/models/modular/meshes/concert/concert_steering_connection_module.stl" scale="0.001 0.001 0.001"/>
      </geometry>
    </visual>
    <collision>
      <origin rpy="0.0 -0.0 0.0" xyz="0 0 0"/>
      <geometry>
        <mesh filename="package://concert_resources/models/modular/meshes/concert/simple/concert_steering_connection_module.stl" scale="0.001 0.001 0.001"/>
      </geometry>
    </collision>
    <inertial>
      <origin rpy="0 0 0" xyz="-0.0079406061 0.0 0.037039629"/>
      <mass value="1.1813661"/>
      <inertia ixx="0.0026106263" ixy="0.0" ixz="0.00017928188" iyy="0.0027438806" iyz="0.0" izz="0.0025223123"/>
    </inertial>
  </link>
  <gazebo reference="J1_B_stator">
    <mu1>0.2</mu1>
    <mu2>0.2</mu2>
    <kp>100000000.0</kp>
    <kd>1.0</kd>
    <maxVel>0.0</maxVel>
    <minDepth>0.0001</minDepth>
    <material>Gazebo/Blue</material>
    <selfCollide>True</selfCollide>
  </gazebo>
  <joint name="J1_B" type="revolute">
    <axis rpy="0 0 0" xyz="0 0 1"/>
    <parent link="J1_B_stator"/>
    <child link="L_1_B"/>
    <origin rpy="1.5707963267948966 -0.0 -1.5707963267948966" xyz="-0.022 0.0 0.06075"/>
    <limit effort="127.0" lower="-2.6" upper="2.6" velocity="8.1"/>
  </joint>
  <link name="L_1_B">
    <visual>
      <origin rpy="3.141592653589793 -0.0 0.0" xyz="0 0 0"/>
      <geometry>
        <mesh filename="package://concert_resources/models/modular/meshes/concert/concert_steering_module_frame.stl" scale="0.001 0.001 0.001"/>
      </geometry>
    </visual>
    <collision>
      <origin rpy="3.141592653589793 -0.0 0.0" xyz="0 0 0"/>
      <geometry>
        <mesh filename="package://concert_resources/models/modular/meshes/concert/simple/concert_steering_module_frame.stl" scale="0.001 0.001 0.001"/>
      </geometry>
    </collision>
    <inertial>
      <origin rpy="0 0 0" xyz="0.090718433 0.0 0.22670598"/>
      <mass value="7.6995028"/>
      <inertia ixx="0.44048889" ixy="-0.03668535" ixz="0.025595962" iyy="0.52073797" iyz="-0.0026667139" izz="0.69985532"/>
    </inertial>
  </link>
  <gazebo reference="L_1_B">
    <mu1>0.2</mu1>
    <mu2>0.2</mu2>
    <kp>100000000.0</kp>
    <kd>1.0</kd>
    <maxVel>0.0</maxVel>
    <minDepth>0.0001</minDepth>
    <material>Gazebo/White</material>
    <selfCollide>True</selfCollide>
  </gazebo>
  <joint name="fixed_J_wheel_B" type="fixed">
    <axis rpy="0 0 0" xyz="0 0 1"/>
    <parent link="L_1_B"/>
    <child link="J_wheel_B_stator"/>
    <origin rpy="-3.141592653589793 1.5707963267948966 0.0" xyz="0.0 0.0 0.37015"/>
  </joint>
  <link name="J_wheel_B_stator">
    <inertial>
      <mass value="0.001"/>
      <inertia ixx="1.0e-06" ixy="0.0" ixz="0.0" iyy="1.0e-06" iyz="0.0" izz="1.0e-06"/>
    </inertial>
  </link>
  <gazebo reference="J_wheel_B_stator"/>
  <joint name="J_wheel_B" type="revolute">
    <axis rpy="0 0 0" xyz="0 0 1"/>
    <parent link="J_wheel_B_stator"/>
    <child link="wheel_B"/>
    <origin rpy="0.0 -0.0 0.0" xyz="0.0 0.0 0.0"/>
    <limit effort="24.0" lower="-10000000000.0" upper="10000000000.0" velocity="9.5"/>
  </joint>
  <link name="wheel_B">
    <visual>
      <origin rpy="0.0 -0.0 0.0" xyz="0 0 0"/>
      <geometry>
        <mesh filename="package://concert_resources/models/modular/meshes/concert/concert_wheel.stl" scale="0.001 0.001 0.001"/>
      </geometry>
    </visual>
    <collision>
      <origin rpy="0.0 -0.0 0.0" xyz="0 0 0"/>
      <geometry>
        <cylinder length="0.1" radius="0.16"/>
      </geometry>
    </collision>
    <inertial>
      <origin rpy="0 0 0" xyz="0.0 0.0 -0.005"/>
      <mass value="4.0116207"/>
      <inertia ixx="0.028580559" ixy="0.0" ixz="0.0" iyy="0.028580559" iyz="0.0" izz="0.044954065"/>
    </inertial>
  </link>
  <gazebo reference="wheel_B">
    <material>Gazebo/Residential</material>
    <selfCollide>True</selfCollide>
    <collision>
      <surface>
        <friction>
          <ode>
            <mu>1.0</mu>
            <mu2>1.0</mu2>
          </ode>
          <bullet>
            <friction>1.0</friction>
            <friction2>1.0</friction2>
          </bullet>
        </friction>
        <contact>
          <ode>
            <kp>2100000</kp>
            <kd>1</kd>
            <max_vel>100</max_vel>
          </ode>
          <bullet>
            <soft_cfm>0.007</soft_cfm>
            <soft_erp>0.25</soft_erp>
            <kp>1000000</kp>
            <kd>5</kd>
          </bullet>
        </contact>
      </surface>
    </collision>
  </gazebo>
  <joint name="fixed_J1_C" type="fixed">
    <axis rpy="0 0 0" xyz="0 0 1"/>
    <parent link="mobile_base"/>
    <child link="J1_C_stator"/>
    <origin rpy="-0.0 -1.5707963267948966 0.0" xyz="-0.37925 0.3125 -0.195"/>
  </joint>
  <link name="J1_C_stator">
    <visual>
      <origin rpy="0.0 -0.0 0.0" xyz="0 0 0"/>
      <geometry>
        <mesh filename="package://concert_resources/models/modular/meshes/concert/concert_steering_connection_module.stl" scale="0.001 0.001 0.001"/>
      </geometry>
    </visual>
    <collision>
      <origin rpy="0.0 -0.0 0.0" xyz="0 0 0"/>
      <geometry>
        <mesh filename="package://concert_resources/models/modular/meshes/concert/simple/concert_steering_connection_module.stl" scale="0.001 0.001 0.001"/>
      </geometry>
    </collision>
    <inertial>
      <origin rpy="0 0 0" xyz="-0.0079406061 0.0 0.037039629"/>
      <mass value="1.1813661"/>
      <inertia ixx="0.0026106263" ixy="0.0" ixz="0.00017928188" iyy="0.0027438806" iyz="0.0" izz="0.0025223123"/>
    </inertial>
  </link>
  <gazebo reference="J1_C_stator">
    <mu1>0.2</mu1>
    <mu2>0.2</mu2>
    <kp>100000000.0</kp>
    <kd>1.0</kd>
    <maxVel>0.0</maxVel>
    <minDepth>0.0001</minDepth>
    <material>Gazebo/Blue</material>
    <selfCollide>True</selfCollide>
  </gazebo>
  <joint name="J1_C" type="revolute">
    <axis rpy="0 0 0" xyz="0 0 1"/>
    <parent link="J1_C_stator"/>
    <child link="L_1_C"/>
    <origin rpy="1.5707963267948966 -0.0 -1.5707963267948966" xyz="-0.022 0.0 0.06075"/>
    <limit effort="127.0" lower="-2.6" upper="2.6" velocity="8.1"/>
  </joint>
  <link name="L_1_C">
    <visual>
      <origin rpy="3.141592653589793 -0.0 0.0" xyz="0 0 0"/>
      <geometry>
        <mesh filename="package://concert_resources/models/modular/meshes/concert/concert_steering_module_frame.stl" scale="0.001 0.001 0.001"/>
      </geometry>
    </visual>
    <collision>
      <origin rpy="3.141592653589793 -0.0 0.0" xyz="0 0 0"/>
      <geometry>
        <mesh filename="package://concert_resources/models/modular/meshes/concert/simple/concert_steering_module_frame.stl" scale="0.001 0.001 0.001"/>
      </geometry>
    </collision>
    <inertial>
      <origin rpy="0 0 0" xyz="0.090718433 0.0 0.22670598"/>
      <mass value="7.6995028"/>
      <inertia ixx="0.44048889" ixy="-0.03668535" ixz="0.025595962" iyy="0.52073797" iyz="-0.0026667139" izz="0.69985532"/>
    </inertial>
  </link>
  <gazebo reference="L_1_C">
    <mu1>0.2</mu1>
    <mu2>0.2</mu2>
    <kp>100000000.0</kp>
    <kd>1.0</kd>
    <maxVel>0.0</maxVel>
    <minDepth>0.0001</minDepth>
    <material>Gazebo/White</material>
    <selfCollide>True</selfCollide>
  </gazebo>
  <joint name="fixed_J_wheel_C" type="fixed">
    <axis rpy="0 0 0" xyz="0 0 1"/>
    <parent link="L_1_C"/>
    <child link="J_wheel_C_stator"/>
    <origin rpy="-3.141592653589793 1.5707963267948966 0.0" xyz="0.0 0.0 0.37015"/>
  </joint>
  <link name="J_wheel_C_stator">
    <inertial>
      <mass value="0.001"/>
      <inertia ixx="1.0e-06" ixy="0.0" ixz="0.0" iyy="1.0e-06" iyz="0.0" izz="1.0e-06"/>
    </inertial>
  </link>
  <gazebo reference="J_wheel_C_stator"/>
  <joint name="J_wheel_C" type="revolute">
    <axis rpy="0 0 0" xyz="0 0 1"/>
    <parent link="J_wheel_C_stator"/>
    <child link="wheel_C"/>
    <origin rpy="0.0 -0.0 0.0" xyz="0.0 0.0 0.0"/>
    <limit effort="24.0" lower="-10000000000.0" upper="10000000000.0" velocity="9.5"/>
  </joint>
  <link name="wheel_C">
    <visual>
      <origin rpy="0.0 -0.0 0.0" xyz="0 0 0"/>
      <geometry>
        <mesh filename="package://concert_resources/models/modular/meshes/concert/concert_wheel.stl" scale="0.001 0.001 0.001"/>
      </geometry>
    </visual>
    <collision>
      <origin rpy="0.0 -0.0 0.0" xyz="0 0 0"/>
      <geometry>
        <cylinder length="0.1" radius="0.16"/>
      </geometry>
    </collision>
    <inertial>
      <origin rpy="0 0 0" xyz="0.0 0.0 -0.005"/>
      <mass value="4.0116207"/>
      <inertia ixx="0.028580559" ixy="0.0" ixz="0.0" iyy="0.028580559" iyz="0.0" izz="0.044954065"/>
    </inertial>
  </link>
  <gazebo reference="wheel_C">
    <material>Gazebo/Residential</material>
    <selfCollide>True</selfCollide>
    <collision>
      <surface>
        <friction>
          <ode>
            <mu>1.0</mu>
            <mu2>1.0</mu2>
          </ode>
          <bullet>
            <friction>1.0</friction>
            <friction2>1.0</friction2>
          </bullet>
        </friction>
        <contact>
          <ode>
            <kp>2100000</kp>
            <kd>1</kd>
            <max_vel>100</max_vel>
          </ode>
          <bullet>
            <soft_cfm>0.007</soft_cfm>
            <soft_erp>0.25</soft_erp>
            <kp>1000000</kp>
            <kd>5</kd>
          </bullet>
        </contact>
      </surface>
    </collision>
  </gazebo>
  <joint name="fixed_J1_D" type="fixed">
    <axis rpy="0 0 0" xyz="0 0 1"/>
    <parent link="mobile_base"/>
    <child link="J1_D_stator"/>
    <origin rpy="-0.0 -1.5707963267948966 0.0" xyz="-0.37925 -0.3125 -0.195"/>
  </joint>
  <link name="J1_D_stator">
    <visual>
      <origin rpy="0.0 -0.0 0.0" xyz="0 0 0"/>
      <geometry>
        <mesh filename="package://concert_resources/models/modular/meshes/concert/concert_steering_connection_module.stl" scale="0.001 0.001 0.001"/>
      </geometry>
    </visual>
    <collision>
      <origin rpy="0.0 -0.0 0.0" xyz="0 0 0"/>
      <geometry>
        <mesh filename="package://concert_resources/models/modular/meshes/concert/simple/concert_steering_connection_module.stl" scale="0.001 0.001 0.001"/>
      </geometry>
    </collision>
    <inertial>
      <origin rpy="0 0 0" xyz="-0.0079406061 0.0 0.037039629"/>
      <mass value="1.1813661"/>
      <inertia ixx="0.0026106263" ixy="0.0" ixz="0.00017928188" iyy="0.0027438806" iyz="0.0" izz="0.0025223123"/>
    </inertial>
  </link>
  <gazebo reference="J1_D_stator">
    <mu1>0.2</mu1>
    <mu2>0.2</mu2>
    <kp>100000000.0</kp>
    <kd>1.0</kd>
    <maxVel>0.0</maxVel>
    <minDepth>0.0001</minDepth>
    <material>Gazebo/Blue</material>
    <selfCollide>True</selfCollide>
  </gazebo>
  <joint name="J1_D" type="revolute">
    <axis rpy="0 0 0" xyz="0 0 1"/>
    <parent link="J1_D_stator"/>
    <child link="L_1_D"/>
    <origin rpy="-1.5707963267948966 -0.0 1.5707963267948966" xyz="-0.022 0.0 0.06075"/>
    <limit effort="127.0" lower="-2.6" upper="2.6" velocity="8.1"/>
  </joint>
  <link name="L_1_D">
    <visual>
      <origin rpy="3.141592653589793 -0.0 0.0" xyz="0 0 0"/>
      <geometry>
        <mesh filename="package://concert_resources/models/modular/meshes/concert/concert_steering_module_frame.stl" scale="0.001 0.001 0.001"/>
      </geometry>
    </visual>
    <collision>
      <origin rpy="3.141592653589793 -0.0 0.0" xyz="0 0 0"/>
      <geometry>
        <mesh filename="package://concert_resources/models/modular/meshes/concert/simple/concert_steering_module_frame.stl" scale="0.001 0.001 0.001"/>
      </geometry>
    </collision>
    <inertial>
      <origin rpy="0 0 0" xyz="0.090718433 0.0 0.22670598"/>
      <mass value="7.6995028"/>
      <inertia ixx="0.44048889" ixy="-0.03668535" ixz="0.025595962" iyy="0.52073797" iyz="-0.0026667139" izz="0.69985532"/>
    </inertial>
  </link>
  <gazebo reference="L_1_D">
    <mu1>0.2</mu1>
    <mu2>0.2</mu2>
    <kp>100000000.0</kp>
    <kd>1.0</kd>
    <maxVel>0.0</maxVel>
    <minDepth>0.0001</minDepth>
    <material>Gazebo/White</material>
    <selfCollide>True</selfCollide>
  </gazebo>
  <joint name="fixed_J_wheel_D" type="fixed">
    <axis rpy="0 0 0" xyz="0 0 1"/>
    <parent link="L_1_D"/>
    <child link="J_wheel_D_stator"/>
    <origin rpy="-3.141592653589793 1.5707963267948966 0.0" xyz="0.0 0.0 0.37015"/>
  </joint>
  <link name="J_wheel_D_stator">
    <inertial>
      <mass value="0.001"/>
      <inertia ixx="1.0e-06" ixy="0.0" ixz="0.0" iyy="1.0e-06" iyz="0.0" izz="1.0e-06"/>
    </inertial>
  </link>
  <gazebo reference="J_wheel_D_stator"/>
  <joint name="J_wheel_D" type="revolute">
    <axis rpy="0 0 0" xyz="0 0 1"/>
    <parent link="J_wheel_D_stator"/>
    <child link="wheel_D"/>
    <origin rpy="0.0 -0.0 0.0" xyz="0.0 0.0 0.0"/>
    <limit effort="24.0" lower="-10000000000.0" upper="10000000000.0" velocity="9.5"/>
  </joint>
  <link name="wheel_D">
    <visual>
      <origin rpy="0.0 -0.0 0.0" xyz="0 0 0"/>
      <geometry>
        <mesh filename="package://concert_resources/models/modular/meshes/concert/concert_wheel.stl" scale="0.001 0.001 0.001"/>
      </geometry>
    </visual>
    <collision>
      <origin rpy="0.0 -0.0 0.0" xyz="0 0 0"/>
      <geometry>
        <cylinder length="0.1" radius="0.16"/>
      </geometry>
    </collision>
    <inertial>
      <origin rpy="0 0 0" xyz="0.0 0.0 -0.005"/>
      <mass value="4.0116207"/>
      <inertia ixx="0.028580559" ixy="0.0" ixz="0.0" iyy="0.028580559" iyz="0.0" izz="0.044954065"/>
    </inertial>
  </link>
  <gazebo reference="wheel_D">
    <material>Gazebo/Residential</material>
    <selfCollide>True</selfCollide>
    <collision>
      <surface>
        <friction>
          <ode>
            <mu>1.0</mu>
            <mu2>1.0</mu2>
          </ode>
          <bullet>
            <friction>1.0</friction>
            <friction2>1.0</friction2>
          </bullet>
        </friction>
        <contact>
          <ode>
            <kp>2100000</kp>
            <kd>1</kd>
            <max_vel>100</max_vel>
          </ode>
          <bullet>
            <soft_cfm>0.007</soft_cfm>
            <soft_erp>0.25</soft_erp>
            <kp>1000000</kp>
            <kd>5</kd>
          </bullet>
        </contact>
      </surface>
    </collision>
  </gazebo>
  <joint name="fixed_J1_E" type="fixed">
    <axis rpy="0 0 0" xyz="0 0 1"/>
    <parent link="mobile_base"/>
    <child link="J1_E_stator"/>
    <origin rpy="0.0 -0.0 3.141592653589793" xyz="0.2 0.0 0.016"/>
  </joint>
  <link name="J1_E_stator">
    <visual>
      <origin rpy="0.0 -0.0 0.0" xyz="0 0 0"/>
      <geometry>
        <mesh filename="package://concert_resources/models/modular/meshes/concert/concert_yaw-base.stl" scale="0.001 0.001 0.001"/>
      </geometry>
    </visual>
    <collision>
      <origin rpy="0.0 -0.0 0.0" xyz="0 0 0"/>
      <geometry>
        <mesh filename="package://concert_resources/models/modular/meshes/concert/simple/concert_yaw-base.stl" scale="0.001 0.001 0.001"/>
      </geometry>
    </collision>
    <inertial>
      <origin rpy="0 0 0" xyz="0.0 0.0 0.121"/>
      <mass value="3.586681"/>
      <inertia ixx="0.017808349" ixy="1.6625281e-06" ixz="-1.8023262e-05" iyy="0.017503159" iyz="-6.8557387e-05" izz="0.0068844202"/>
    </inertial>
  </link>
  <gazebo reference="J1_E_stator">
    <mu1>0.2</mu1>
    <mu2>0.2</mu2>
    <kp>100000000.0</kp>
    <kd>1.0</kd>
    <maxVel>0.0</maxVel>
    <minDepth>0.0001</minDepth>
    <material>Gazebo/Blue</material>
    <selfCollide>True</selfCollide>
  </gazebo>
  <joint name="J1_E" type="revolute">
    <axis rpy="0 0 0" xyz="0 0 1"/>
    <parent link="J1_E_stator"/>
    <child link="L_1_E"/>
    <origin rpy="0.0 -0.0 0.0" xyz="0.0 0.0 0.22316"/>
    <limit effort="460.0" lower="-3.0" upper="3.0" velocity="2.14"/>
  </joint>
  <link name="L_1_E">
    <visual>
      <origin rpy="0.0 -0.0 0.0" xyz="0 0 0"/>
      <geometry>
        <mesh filename="package://concert_resources/models/modular/meshes/concert/concert_yaw-link.stl" scale="0.001 0.001 0.001"/>
      </geometry>
    </visual>
    <collision>
      <origin rpy="0.0 -0.0 0.0" xyz="0 0 0"/>
      <geometry>
        <mesh filename="package://concert_resources/models/modular/meshes/concert/simple/concert_yaw-link.stl" scale="0.001 0.001 0.001"/>
      </geometry>
    </collision>
    <inertial>
      <origin rpy="0 0 0" xyz="0.0 0.0 0.001875"/>
      <mass value="0.57797267"/>
      <inertia ixx="0.00098277371" ixy="9.0821713e-08" ixz="-7.1612945e-08" iyy="0.0009834362" iyz="0.0" izz="0.0016259552"/>
    </inertial>
  </link>
  <gazebo reference="L_1_E">
    <mu1>0.2</mu1>
    <mu2>0.2</mu2>
    <kp>100000000.0</kp>
    <kd>1.0</kd>
    <maxVel>0.0</maxVel>
    <minDepth>0.0001</minDepth>
    <material>Gazebo/White</material>
    <selfCollide>True</selfCollide>
  </gazebo>
  <joint name="fixed_J2_E" type="fixed">
    <axis rpy="0 0 0" xyz="0 0 1"/>
    <parent link="L_1_E"/>
    <child link="J2_E_stator"/>
    <origin rpy="0.0 -0.0 0.0" xyz="0.0 0.0 0.02184"/>
  </joint>
  <link name="J2_E_stator">
    <visual>
      <origin rpy="0.0 -0.0 0.0" xyz="0 0 0"/>
      <geometry>
        <mesh filename="package://concert_resources/models/modular/meshes/concert/concert_elbow-base.stl" scale="0.001 0.001 0.001"/>
      </geometry>
    </visual>
    <collision>
      <origin rpy="0.0 -0.0 0.0" xyz="0 0 0"/>
      <geometry>
        <mesh filename="package://concert_resources/models/modular/meshes/concert/simple/concert_elbow-base.stl" scale="0.001 0.001 0.001"/>
      </geometry>
    </collision>
    <inertial>
      <origin rpy="0 0 0" xyz="-0.001149215 0.042825109 0.076804506"/>
      <mass value="3.6144181"/>
      <inertia ixx="0.015371313" ixy="-9.9563906e-05" ixz="9.0045644e-06" iyy="0.0086766316" iyz="-0.0018673171" izz="0.013320926"/>
    </inertial>
  </link>
  <gazebo reference="J2_E_stator">
    <mu1>0.2</mu1>
    <mu2>0.2</mu2>
    <kp>100000000.0</kp>
    <kd>1.0</kd>
    <maxVel>0.0</maxVel>
    <minDepth>0.0001</minDepth>
    <material>Gazebo/Blue</material>
    <selfCollide>True</selfCollide>
  </gazebo>
  <joint name="J2_E" type="revolute">
    <axis rpy="0 0 0" xyz="0 0 1"/>
    <parent link="J2_E_stator"/>
    <child link="L_2_E"/>
    <origin rpy="-1.5707963267948966 -0.0 0.0" xyz="0.0 0.13666 0.0875"/>
    <limit effort="460.0" lower="-3.0" upper="3.0" velocity="2.14"/>
  </joint>
  <link name="L_2_E">
    <visual>
      <origin rpy="0.0 -0.0 0.0" xyz="0 0 0"/>
      <geometry>
        <mesh filename="package://concert_resources/models/modular/meshes/concert/concert_elbow-link.stl" scale="0.001 0.001 0.001"/>
      </geometry>
    </visual>
    <collision>
      <origin rpy="0.0 -0.0 0.0" xyz="0 0 0"/>
      <geometry>
        <mesh filename="package://concert_resources/models/modular/meshes/concert/simple/concert_elbow-link.stl" scale="0.001 0.001 0.001"/>
      </geometry>
    </collision>
    <inertial>
      <origin rpy="0 0 0" xyz="0.0 -0.028238874 0.017527776"/>
      <mass value="1.1481338"/>
      <inertia ixx="0.0034928397" ixy="-1.0903971e-05" ixz="6.2736548e-06" iyy="0.0029687575" iyz="0.00031199793" izz="0.0042223026"/>
    </inertial>
  </link>
  <gazebo reference="L_2_E">
    <mu1>0.2</mu1>
    <mu2>0.2</mu2>
    <kp>100000000.0</kp>
    <kd>1.0</kd>
    <maxVel>0.0</maxVel>
    <minDepth>0.0001</minDepth>
    <material>Gazebo/White</material>
    <selfCollide>True</selfCollide>
  </gazebo>
  <joint name="fixed_J3_E" type="fixed">
    <axis rpy="0 0 0" xyz="0 0 1"/>
    <parent link="L_2_E"/>
    <child link="J3_E_stator"/>
    <origin rpy="-1.5707963267948966 -0.0 3.141592653589793" xyz="0.0 -0.0875 0.0195"/>
  </joint>
  <link name="J3_E_stator">
    <visual>
      <origin rpy="0.0 -0.0 0.0" xyz="0 0 0"/>
      <geometry>
        <mesh filename="package://concert_resources/models/modular/meshes/concert/concert_yaw-base.stl" scale="0.001 0.001 0.001"/>
      </geometry>
    </visual>
    <collision>
      <origin rpy="0.0 -0.0 0.0" xyz="0 0 0"/>
      <geometry>
        <mesh filename="package://concert_resources/models/modular/meshes/concert/simple/concert_yaw-base.stl" scale="0.001 0.001 0.001"/>
      </geometry>
    </collision>
    <inertial>
      <origin rpy="0 0 0" xyz="0.0 0.0 0.11767718"/>
      <mass value="3.2592751"/>
      <inertia ixx="0.017046707" ixy="-2.9108359e-07" ixz="-6.3074987e-06" iyy="0.016747265" iyz="-5.7883896e-05" izz="0.0060549298"/>
    </inertial>
  </link>
  <gazebo reference="J3_E_stator">
    <mu1>0.2</mu1>
    <mu2>0.2</mu2>
    <kp>100000000.0</kp>
    <kd>1.0</kd>
    <maxVel>0.0</maxVel>
    <minDepth>0.0001</minDepth>
    <material>Gazebo/Blue</material>
    <selfCollide>True</selfCollide>
  </gazebo>
  <joint name="J3_E" type="revolute">
    <axis rpy="0 0 0" xyz="0 0 1"/>
    <parent link="J3_E_stator"/>
    <child link="L_3_E"/>
    <origin rpy="0.0 -0.0 0.0" xyz="0.0 0.0 0.22316"/>
    <limit effort="314.0" lower="-3.0" upper="3.0" velocity="2.85"/>
  </joint>
  <link name="L_3_E">
    <visual>
      <origin rpy="0.0 -0.0 0.0" xyz="0 0 0"/>
      <geometry>
        <mesh filename="package://concert_resources/models/modular/meshes/concert/concert_yaw-link.stl" scale="0.001 0.001 0.001"/>
      </geometry>
    </visual>
    <collision>
      <origin rpy="0.0 -0.0 0.0" xyz="0 0 0"/>
      <geometry>
        <mesh filename="package://concert_resources/models/modular/meshes/concert/simple/concert_yaw-link.stl" scale="0.001 0.001 0.001"/>
      </geometry>
    </collision>
    <inertial>
      <origin rpy="0 0 0" xyz="0.0 0.0 -0.02"/>
      <mass value="0.56725368"/>
      <inertia ixx="0.00097738346" ixy="9.078518e-08" ixz="5.0589486e-08" iyy="0.00097804563" iyz="0.0" izz="0.001617678"/>
    </inertial>
  </link>
  <gazebo reference="L_3_E">
    <mu1>0.2</mu1>
    <mu2>0.2</mu2>
    <kp>100000000.0</kp>
    <kd>1.0</kd>
    <maxVel>0.0</maxVel>
    <minDepth>0.0001</minDepth>
    <material>Gazebo/White</material>
    <selfCollide>True</selfCollide>
  </gazebo>
  <joint name="fixed_J4_E" type="fixed">
    <axis rpy="0 0 0" xyz="0 0 1"/>
    <parent link="L_3_E"/>
    <child link="J4_E_stator"/>
    <origin rpy="0.0 -0.0 0.0" xyz="0.0 0.0 0.02184"/>
  </joint>
  <link name="J4_E_stator">
    <visual>
      <origin rpy="0.0 -0.0 0.0" xyz="0 0 0"/>
      <geometry>
        <mesh filename="package://concert_resources/models/modular/meshes/concert/concert_elbow-base.stl" scale="0.001 0.001 0.001"/>
      </geometry>
    </visual>
    <collision>
      <origin rpy="0.0 -0.0 0.0" xyz="0 0 0"/>
      <geometry>
        <mesh filename="package://concert_resources/models/modular/meshes/concert/simple/concert_elbow-base.stl" scale="0.001 0.001 0.001"/>
      </geometry>
    </collision>
    <inertial>
      <origin rpy="0 0 0" xyz="-0.001149215 0.042825109 0.076804506"/>
      <mass value="3.6144181"/>
      <inertia ixx="0.015371313" ixy="-9.9563906e-05" ixz="9.0045644e-06" iyy="0.0086766316" iyz="-0.0018673171" izz="0.013320926"/>
    </inertial>
  </link>
  <gazebo reference="J4_E_stator">
    <mu1>0.2</mu1>
    <mu2>0.2</mu2>
    <kp>100000000.0</kp>
    <kd>1.0</kd>
    <maxVel>0.0</maxVel>
    <minDepth>0.0001</minDepth>
    <material>Gazebo/Blue</material>
    <selfCollide>True</selfCollide>
  </gazebo>
  <joint name="J4_E" type="revolute">
    <axis rpy="0 0 0" xyz="0 0 1"/>
    <parent link="J4_E_stator"/>
    <child link="L_4_E"/>
    <origin rpy="-1.5707963267948966 -0.0 0.0" xyz="0.0 0.13666 0.0875"/>
    <limit effort="460.0" lower="-3.0" upper="3.0" velocity="2.14"/>
  </joint>
  <link name="L_4_E">
    <visual>
      <origin rpy="0.0 -0.0 0.0" xyz="0 0 0"/>
      <geometry>
        <mesh filename="package://concert_resources/models/modular/meshes/concert/concert_elbow-link.stl" scale="0.001 0.001 0.001"/>
      </geometry>
    </visual>
    <collision>
      <origin rpy="0.0 -0.0 0.0" xyz="0 0 0"/>
      <geometry>
        <mesh filename="package://concert_resources/models/modular/meshes/concert/simple/concert_elbow-link.stl" scale="0.001 0.001 0.001"/>
      </geometry>
    </collision>
    <inertial>
      <origin rpy="0 0 0" xyz="0.0 -0.028238874 0.017527776"/>
      <mass value="1.1481338"/>
      <inertia ixx="0.0034928397" ixy="-1.0903971e-05" ixz="6.2736548e-06" iyy="0.0029687575" iyz="0.00031199793" izz="0.0042223026"/>
    </inertial>
  </link>
  <gazebo reference="L_4_E">
    <mu1>0.2</mu1>
    <mu2>0.2</mu2>
    <kp>100000000.0</kp>
    <kd>1.0</kd>
    <maxVel>0.0</maxVel>
    <minDepth>0.0001</minDepth>
    <material>Gazebo/White</material>
    <selfCollide>True</selfCollide>
  </gazebo>
  <joint name="fixed_J5_E" type="fixed">
    <axis rpy="0 0 0" xyz="0 0 1"/>
    <parent link="L_4_E"/>
    <child link="J5_E_stator"/>
    <origin rpy="-1.5707963267948966 -0.0 3.141592653589793" xyz="0.0 -0.0875 0.0195"/>
  </joint>
  <link name="J5_E_stator">
    <visual>
      <origin rpy="0.0 -0.0 0.0" xyz="0 0 0"/>
      <geometry>
        <mesh filename="package://concert_resources/models/modular/meshes/concert/concert_yaw-base.stl" scale="0.001 0.001 0.001"/>
      </geometry>
    </visual>
    <collision>
      <origin rpy="0.0 -0.0 0.0" xyz="0 0 0"/>
      <geometry>
        <mesh filename="package://concert_resources/models/modular/meshes/concert/simple/concert_yaw-base.stl" scale="0.001 0.001 0.001"/>
      </geometry>
    </collision>
    <inertial>
      <origin rpy="0 0 0" xyz="0.0 0.0 0.11767718"/>
      <mass value="3.2592751"/>
      <inertia ixx="0.017046707" ixy="-2.9108359e-07" ixz="-6.3074987e-06" iyy="0.016747265" iyz="-5.7883896e-05" izz="0.0060549298"/>
    </inertial>
  </link>
  <gazebo reference="J5_E_stator">
    <mu1>0.2</mu1>
    <mu2>0.2</mu2>
    <kp>100000000.0</kp>
    <kd>1.0</kd>
    <maxVel>0.0</maxVel>
    <minDepth>0.0001</minDepth>
    <material>Gazebo/Blue</material>
    <selfCollide>True</selfCollide>
  </gazebo>
  <joint name="J5_E" type="revolute">
    <axis rpy="0 0 0" xyz="0 0 1"/>
    <parent link="J5_E_stator"/>
    <child link="L_5_E"/>
    <origin rpy="0.0 -0.0 0.0" xyz="0.0 0.0 0.22316"/>
    <limit effort="314.0" lower="-3.0" upper="3.0" velocity="2.85"/>
  </joint>
  <link name="L_5_E">
    <visual>
      <origin rpy="0.0 -0.0 0.0" xyz="0 0 0"/>
      <geometry>
        <mesh filename="package://concert_resources/models/modular/meshes/concert/concert_yaw-link.stl" scale="0.001 0.001 0.001"/>
      </geometry>
    </visual>
    <collision>
      <origin rpy="0.0 -0.0 0.0" xyz="0 0 0"/>
      <geometry>
        <mesh filename="package://concert_resources/models/modular/meshes/concert/simple/concert_yaw-link.stl" scale="0.001 0.001 0.001"/>
      </geometry>
    </collision>
    <inertial>
      <origin rpy="0 0 0" xyz="0.0 0.0 -0.02"/>
      <mass value="0.56725368"/>
      <inertia ixx="0.00097738346" ixy="9.078518e-08" ixz="5.0589486e-08" iyy="0.00097804563" iyz="0.0" izz="0.001617678"/>
    </inertial>
  </link>
  <gazebo reference="L_5_E">
    <mu1>0.2</mu1>
    <mu2>0.2</mu2>
    <kp>100000000.0</kp>
    <kd>1.0</kd>
    <maxVel>0.0</maxVel>
    <minDepth>0.0001</minDepth>
    <material>Gazebo/White</material>
    <selfCollide>True</selfCollide>
  </gazebo>
  <joint name="fixed_J6_E" type="fixed">
    <axis rpy="0 0 0" xyz="0 0 1"/>
    <parent link="L_5_E"/>
    <child link="J6_E_stator"/>
    <origin rpy="0.0 -0.0 0.0" xyz="0.0 0.0 0.02184"/>
  </joint>
  <link name="J6_E_stator">
    <visual>
      <origin rpy="0.0 -0.0 0.0" xyz="0 0 0"/>
      <geometry>
        <mesh filename="package://concert_resources/models/modular/meshes/concert/concert_elbow-base.stl" scale="0.001 0.001 0.001"/>
      </geometry>
    </visual>
    <collision>
      <origin rpy="0.0 -0.0 0.0" xyz="0 0 0"/>
      <geometry>
        <mesh filename="package://concert_resources/models/modular/meshes/concert/simple/concert_elbow-base.stl" scale="0.001 0.001 0.001"/>
      </geometry>
    </collision>
    <inertial>
      <origin rpy="0 0 0" xyz="-0.0011761517 0.041312534 0.075772157"/>
      <mass value="3.3057881"/>
      <inertia ixx="0.014381278" ixy="-8.2901107e-05" ixz="2.7564183e-05" iyy="0.0078716547" iyz="-0.0018208015" izz="0.012353539"/>
    </inertial>
  </link>
  <gazebo reference="J6_E_stator">
    <mu1>0.2</mu1>
    <mu2>0.2</mu2>
    <kp>100000000.0</kp>
    <kd>1.0</kd>
    <maxVel>0.0</maxVel>
    <minDepth>0.0001</minDepth>
    <material>Gazebo/Blue</material>
    <selfCollide>True</selfCollide>
  </gazebo>
  <joint name="J6_E" type="revolute">
    <axis rpy="0 0 0" xyz="0 0 1"/>
    <parent link="J6_E_stator"/>
    <child link="L_6_E"/>
    <origin rpy="-1.5707963267948966 -0.0 0.0" xyz="0.0 0.13666 0.0875"/>
    <limit effort="314.0" lower="-3.0" upper="3.0" velocity="2.85"/>
  </joint>
  <link name="L_6_E">
    <visual>
      <origin rpy="0.0 -0.0 0.0" xyz="0 0 0"/>
      <geometry>
        <mesh filename="package://concert_resources/models/modular/meshes/concert/concert_elbow-link.stl" scale="0.001 0.001 0.001"/>
      </geometry>
    </visual>
    <collision>
      <origin rpy="0.0 -0.0 0.0" xyz="0 0 0"/>
      <geometry>
        <mesh filename="package://concert_resources/models/modular/meshes/concert/simple/concert_elbow-link.stl" scale="0.001 0.001 0.001"/>
      </geometry>
    </collision>
    <inertial>
      <origin rpy="0 0 0" xyz="0.0 -0.028683616 0.017545874"/>
      <mass value="1.1588784"/>
      <inertia ixx="0.0034928397" ixy="-1.0903971e-05" ixz="6.2736548e-06" iyy="0.0029687575" iyz="0.00031199793" izz="0.0042223026"/>
    </inertial>
  </link>
  <gazebo reference="L_6_E">
    <mu1>0.2</mu1>
    <mu2>0.2</mu2>
    <kp>100000000.0</kp>
    <kd>1.0</kd>
    <maxVel>0.0</maxVel>
    <minDepth>0.0001</minDepth>
    <material>Gazebo/White</material>
    <selfCollide>True</selfCollide>
  </gazebo>
  <link name="ee_E">
    <visual>
      <origin rpy="0 0 0" xyz="0 0 -0.1"/>
      <geometry>
        <cylinder length="0.2" radius="0.02"/>
      </geometry>
      <material name="blue"/>
    </visual>
    <collision>
      <origin rpy="0 0 0" xyz="0 0 -0.1"/>
      <geometry>
        <cylinder length="0.2" radius="0.02"/>
      </geometry>
    </collision>
    <inertial>
      <origin rpy="0 0 0" xyz="0 0 0.1"/>
      <mass value="1.0"/>
      <inertia ixx="0.003433333333333334" ixy="0.0" ixz="0.0" iyy="0.003433333333333334" iyz="0.0" izz="0.0002"/>
    </inertial>
  </link>
  <joint name="L_6_fixed_joint_1_E" type="fixed">
    <axis rpy="0 0 0" xyz="0 0 1"/>
    <parent link="L_6_E"/>
    <child link="ee_E"/>
    <origin rpy="-1.5707963267948966 -0.0 3.141592653589793" xyz="0.0 -0.2875 0.0195"/>
  </joint>
</robot>

