<?xml version="1.0" encoding="utf-8"?>
<robot name="ModularBot">
  <material name="blue">
    <color rgba="0 0 0.8 1"/>
  </material>
  <material name="black">
    <color rgba="0 0 0 1"/>
  </material>
  <material name="white">
    <color rgba="1 1 1 1"/>
  </material>
  <material name="grey">
    <color rgba="0.5 0.5 0.5 1"/>
  </material>
  <material name="red">
    <color rgba="1 0 0 1"/>
  </material>
  <material name="green">
    <color rgba="0 1 0 1"/>
  </material>
  <material name="yellow">
    <color rgba="1 1 0 1"/>
  </material>
  <material name="tree_green">
    <color rgba="0.13 0.54 0.13 1"/>
  </material>
  <origin rpy="0 0 0" xyz="0.0 0.0 0.8"/>
  <link name="base_link">
    <inertial>
      <mass value="0.001"/>
      <inertia ixx="1.0e-06" ixy="0.0" ixz="0.0" iyy="1.0e-06" iyz="0.0" izz="1.0e-06"/>
    </inertial>
  </link>
  <gazebo>
    <plugin filename="libxbot2_gz_joint_server.so" name="xbot2_gz_joint_server">
      <pid>
        <gain d="10" name="small_mot" p="100"/>
        <gain d="50" name="medium_mot" p="500"/>
        <gain d="100" name="big_mot" p="1000"/>
        <gain name="J1_A" profile="medium_mot"/>
        <gain d="50" name="J_wheel_A" p="0"/>
        <gain name="J1_B" profile="medium_mot"/>
        <gain d="50" name="J_wheel_B" p="0"/>
        <gain name="J1_C" profile="medium_mot"/>
        <gain d="50" name="J_wheel_C" p="0"/>
        <gain name="J1_D" profile="medium_mot"/>
        <gain d="50" name="J_wheel_D" p="0"/>
        <gain name="J1_E" profile="small_mot"/>
        <gain name="J2_E" profile="medium_mot"/>
        <gain name="J3_E" profile="small_mot"/>
        <gain name="J4_E" profile="medium_mot"/>
        <gain name="J5_E" profile="small_mot"/>
        <gain name="J6_E" profile="medium_mot"/>
      </pid>
    </plugin>
  </gazebo>
  <joint name="fixed" type="fixed">
    <parent link="base_link"/>
    <child link="mobile_base"/>
    <axis rpy="0 0 0" xyz="0 0 1"/>
    <origin rpy="0.0 0.0 0.0" xyz="0.0 0.0 0.0"/>
  </joint>
  <link name="mobile_base">
    <visual>
      <origin rpy="0.0 -0.0 0.0" xyz="0 0 0"/>
      <geometry>
        <mesh filename="package://concert_resources/models/modular/meshes/concert/concert_central_body.stl" scale="0.001 0.001 0.001"/>
      </geometry>
    </visual>
    <collision>
      <origin rpy="0.0 -0.0 0.0" xyz="0 0 0"/>
      <geometry>
        <mesh filename="package://concert_resources/models/modular/meshes/concert/simple/concert_central_body.stl" scale="0.001 0.001 0.001"/>
      </geometry>
    </collision>
    <inertial>
      <origin rpy="0 0 0" xyz="0.012213513 0.0 -0.21761073"/>
      <mass value="127.57599"/>
      <inertia ixx="19.025397" ixy="-0.62823044" ixz="-0.064261485" iyy="13.251602" iyz="0.91864796" izz="23.575473"/>
    </inertial>
  </link>
  <material name="D435i_camera_front_aluminum">
    <color rgba="0.5 0.5 0.5 1"/>
  </material>
  <!-- camera body, with origin at bottom screw mount -->
  <joint name="D435i_camera_front_joint" type="fixed">
    <origin rpy="0 0.261799 0" xyz="0.402872 0.0 -0.078218"/>
    <parent link="mobile_base"/>
    <child link="D435i_camera_front_bottom_screw_frame"/>
  </joint>
  <link name="D435i_camera_front_bottom_screw_frame"/>
  <joint name="D435i_camera_front_link_joint" type="fixed">
    <origin rpy="0 0 0" xyz="0 0.0175 0.0125"/>
    <parent link="D435i_camera_front_bottom_screw_frame"/>
    <child link="D435i_camera_front_link"/>
  </joint>
  <link name="D435i_camera_front_link">
    <visual>
      <origin rpy="1.5707963267948966 0 1.5707963267948966" xyz="0.0149 -0.0175 0"/>
      <geometry>
        <!-- <box size="${d435i_cam_width} ${d435i_cam_height} ${d435i_cam_depth}"/> -->
        <mesh filename="package://realsense2_description/meshes/d435.dae"/>
        <!--<mesh filename="package://realsense2_description/meshes/d435/d435.dae"/>-->
      </geometry>
      <material name="D435i_camera_front_aluminum"/>
    </visual>
    <collision>
      <origin rpy="0 0 0" xyz="0 -0.0175 0"/>
      <geometry>
        <box size="0.02505 0.09 0.025"/>
      </geometry>
    </collision>
    <inertial>
      <!-- The following are not reliable values, and should not be used for modeling -->
      <mass value="0.564"/>
      <origin xyz="0 0 0"/>
      <inertia ixx="0.003881243" ixy="0.0" ixz="0.0" iyy="0.000498940" iyz="0.0" izz="0.003879257"/>
    </inertial>
  </link>
  <!-- camera depth joints and links -->
  <joint name="D435i_camera_front_depth_joint" type="fixed">
    <origin rpy="0 0 0" xyz="0 0 0"/>
    <parent link="D435i_camera_front_link"/>
    <child link="D435i_camera_front_depth_frame"/>
  </joint>
  <link name="D435i_camera_front_depth_frame"/>
  <joint name="D435i_camera_front_depth_optical_joint" type="fixed">
    <origin rpy="-1.5707963267948966 0 -1.5707963267948966" xyz="0 0 0"/>
    <parent link="D435i_camera_front_depth_frame"/>
    <child link="D435i_camera_front_depth_optical_frame"/>
  </joint>
  <link name="D435i_camera_front_depth_optical_frame"/>
  <!-- camera left IR joints and links -->
  <joint name="D435i_camera_front_left_ir_joint" type="fixed">
    <origin rpy="0 0 0" xyz="0 0.0 0"/>
    <parent link="D435i_camera_front_depth_frame"/>
    <child link="D435i_camera_front_left_ir_frame"/>
  </joint>
  <link name="D435i_camera_front_left_ir_frame"/>
  <joint name="D435i_camera_front_left_ir_optical_joint" type="fixed">
    <origin rpy="-1.5707963267948966 0 -1.5707963267948966" xyz="0 0 0"/>
    <parent link="D435i_camera_front_left_ir_frame"/>
    <child link="D435i_camera_front_left_ir_optical_frame"/>
  </joint>
  <link name="D435i_camera_front_left_ir_optical_frame"/>
  <!-- camera right IR joints and links -->
  <joint name="D435i_camera_front_right_ir_joint" type="fixed">
    <origin rpy="0 0 0" xyz="0 -0.05 0"/>
    <parent link="D435i_camera_front_depth_frame"/>
    <child link="D435i_camera_front_right_ir_frame"/>
  </joint>
  <link name="D435i_camera_front_right_ir_frame"/>
  <joint name="D435i_camera_front_right_ir_optical_joint" type="fixed">
    <origin rpy="-1.5707963267948966 0 -1.5707963267948966" xyz="0 0 0"/>
    <parent link="D435i_camera_front_right_ir_frame"/>
    <child link="D435i_camera_front_right_ir_optical_frame"/>
  </joint>
  <link name="D435i_camera_front_right_ir_optical_frame"/>
  <!-- camera color joints and links -->
  <joint name="D435i_camera_front_color_joint" type="fixed">
    <origin rpy="0 0 0" xyz="0 0.015 0"/>
    <parent link="D435i_camera_front_depth_frame"/>
    <child link="D435i_camera_front_color_frame"/>
  </joint>
  <link name="D435i_camera_front_color_frame"/>
  <joint name="D435i_camera_front_color_optical_joint" type="fixed">
    <origin rpy="-1.5707963267948966 0 -1.5707963267948966" xyz="0 0 0"/>
    <parent link="D435i_camera_front_color_frame"/>
    <child link="D435i_camera_front_color_optical_frame"/>
  </joint>
  <link name="D435i_camera_front_color_optical_frame"/>
  <!-- camera accel joints and links -->
  <joint name="D435i_camera_front_accel_joint" type="fixed">
    <origin rpy="0 0 0" xyz="-0.00174 0.00552 0.0176"/>
    <parent link="D435i_camera_front_link"/>
    <child link="D435i_camera_front_accel_frame"/>
  </joint>
  <link name="D435i_camera_front_accel_frame"/>
  <joint name="D435i_camera_front_accel_optical_joint" type="fixed">
    <origin rpy="-1.5707963267948966 0 -1.5707963267948966" xyz="0 0 0"/>
    <parent link="D435i_camera_front_accel_frame"/>
    <child link="D435i_camera_front_accel_optical_frame"/>
  </joint>
  <link name="D435i_camera_front_accel_optical_frame"/>
  <!-- camera gyro joints and links -->
  <joint name="D435i_camera_front_gyro_joint" type="fixed">
    <origin rpy="0 0 0" xyz="-0.00174 0.00552 0.0176"/>
    <parent link="D435i_camera_front_link"/>
    <child link="D435i_camera_front_gyro_frame"/>
  </joint>
  <link name="D435i_camera_front_gyro_frame"/>
  <joint name="D435i_camera_front_gyro_optical_joint" type="fixed">
    <origin rpy="-1.5707963267948966 0 -1.5707963267948966" xyz="0 0 0"/>
    <parent link="D435i_camera_front_gyro_frame"/>
    <child link="D435i_camera_front_gyro_optical_frame"/>
  </joint>
  <link name="D435i_camera_front_gyro_optical_frame"/>
  <gazebo reference="D435i_camera_front_link">
    <self_collide>0</self_collide>
    <enable_wind>0</enable_wind>
    <kinematic>0</kinematic>
    <!-- <gravity>1</gravity> -->
    <!--<mu>1</mu>-->
    <mu2>1</mu2>
    <fdir1>0 0 0</fdir1>
    <!--<slip1>0</slip1>
      <slip2>0</slip2>-->
    <kp>1e+13</kp>
    <kd>1</kd>
    <!--<max_vel>0.01</max_vel>
      <min_depth>0</min_depth>-->
    <sensor name="D435i_camera_frontcolor" type="camera">
      <camera name="D435i_camera_front">
        <horizontal_fov>1.2112585008840648</horizontal_fov>
        <image>
          <width>1280</width>
          <height>720</height>
          <format>RGB_INT8</format>
        </image>
        <clip>
          <near>0.1</near>
          <far>100</far>
        </clip>
        <noise>
          <type>gaussian</type>
          <mean>0.0</mean>
          <stddev>0.007</stddev>
        </noise>
      </camera>
      <always_on>1</always_on>
      <update_rate>30</update_rate>
      <visualize>True</visualize>
    </sensor>
    <sensor name="D435i_camera_frontired1" type="camera">
      <camera name="D435i_camera_front">
        <horizontal_fov>1.4870205226991688</horizontal_fov>
        <image>
          <width>1280</width>
          <height>720</height>
          <format>L_INT8</format>
        </image>
        <clip>
          <near>0.1</near>
          <far>100</far>
        </clip>
        <noise>
          <type>gaussian</type>
          <mean>0.0</mean>
          <stddev>0.05</stddev>
        </noise>
      </camera>
      <always_on>1</always_on>
      <update_rate>90</update_rate>
      <visualize>false</visualize>
    </sensor>
    <sensor name="D435i_camera_frontired2" type="camera">
      <camera name="D435i_camera_front">
        <horizontal_fov>1.4870205226991688</horizontal_fov>
        <image>
          <width>1280</width>
          <height>720</height>
          <format>L_INT8</format>
        </image>
        <clip>
          <near>0.1</near>
          <far>100</far>
        </clip>
        <noise>
          <type>gaussian</type>
          <mean>0.0</mean>
          <stddev>0.05</stddev>
        </noise>
      </camera>
      <always_on>1</always_on>
      <update_rate>90</update_rate>
      <visualize>false</visualize>
    </sensor>
    <sensor name="D435i_camera_frontdepth" type="depth">
      <camera name="D435i_camera_front">
        <horizontal_fov>1.2112585008840648</horizontal_fov>
        <image>
          <width>1280</width>
          <height>720</height>
        </image>
        <clip>
          <near>0.1</near>
          <far>100</far>
        </clip>
        <noise>
          <type>gaussian</type>
          <mean>0.0</mean>
          <stddev>0.100</stddev>
        </noise>
      </camera>
      <always_on>1</always_on>
      <update_rate>30</update_rate>
      <visualize>false</visualize>
    </sensor>
    <sensor name="D435i_camera_frontaccel" type="imu">
      <always_on>true</always_on>
      <update_rate>300</update_rate>
      <topic>D435i_camera_front/accel/sample</topic>
      <plugin filename="librealsense_gazebo_accel_sensor.so" name="D435i_camera_front_accel_plugin">
        <topicName>D435i_camera_front/accel/sample</topicName>
        <bodyName>D435i_camera_front_link</bodyName>
        <updateRateHZ>300</updateRateHZ>
        <gaussianNoise>0.1</gaussianNoise>
        <xyzOffset>0 0 0</xyzOffset>
        <rpyOffset>0 0 0</rpyOffset>
        <frameName>D435i_camera_front_accel_optical_frame</frameName>
        <initialOrientationAsReference>false</initialOrientationAsReference>
      </plugin>
      <pose>0 0 0 0 0 0</pose>
    </sensor>
    <sensor name="D435i_camera_frontgyro" type="imu">
      <always_on>true</always_on>
      <update_rate>300</update_rate>
      <topic>D435i_camera_front/gyro/sample</topic>
      <plugin filename="librealsense_gazebo_gyro_sensor.so" name="D435i_camera_front_gyro_plugin">
        <topicName>D435i_camera_front/gyro/sample</topicName>
        <bodyName>D435i_camera_front_link</bodyName>
        <updateRateHZ>300</updateRateHZ>
        <gaussianNoise>0.1</gaussianNoise>
        <xyzOffset>0 0 0</xyzOffset>
        <rpyOffset>0 0 0</rpyOffset>
        <frameName>D435i_camera_front_gyro_optical_frame</frameName>
        <initialOrientationAsReference>false</initialOrientationAsReference>
      </plugin>
    </sensor>
  </gazebo>
  <gazebo>
    <plugin filename="librealsense_gazebo_plugin.so" name="D435i_camera_front">
      <prefix>D435i_camera_front</prefix>
      <!-- Color camera settings -->
      <colorUpdateRate>30</colorUpdateRate>
      <colorTopicName>color/image_raw</colorTopicName>
      <colorOpticalframeName>D435i_camera_front_color_optical_frame</colorOpticalframeName>
      <colorCameraInfoTopicName>color/camera_info</colorCameraInfoTopicName>
      <!-- Infrared camera settings -->
      <infraredUpdateRate>90</infraredUpdateRate>
      <infrared1TopicName>infra1/image_rect_raw</infrared1TopicName>
      <infrared2TopicName>infra2/image_rect_raw</infrared2TopicName>
      <infrared1CameraInfoTopicName>infra1/camera_info</infrared1CameraInfoTopicName>
      <infrared2CameraInfoTopicName>infra2/camera_info</infrared2CameraInfoTopicName>
      <infrared1OpticalframeName>D435i_camera_front_left_ir_optical_frame</infrared1OpticalframeName>
      <infrared2OpticalframeName>D435i_camera_front_right_ir_optical_frame</infrared2OpticalframeName>
      <!-- Depth camera settings -->
      <rangeMinDepth>0.2</rangeMinDepth>
      <rangeMaxDepth>10.0</rangeMaxDepth>
      <depthUpdateRate>30</depthUpdateRate>
      <depthTopicName>aligned_depth_to_color/image_raw</depthTopicName>
      <depthCameraInfoTopicName>aligned_depth_to_color/camera_info</depthCameraInfoTopicName>
      <depthOpticalframeName>D435i_camera_front_color_optical_frame</depthOpticalframeName>
      <!-- Pointlcloud settings -->
      <pointCloud>True</pointCloud>
      <pointCloudTopicName>depth/color/points</pointCloudTopicName>
      <pointCloudCutoff>0.5</pointCloudCutoff>
    </plugin>
  </gazebo>
  <material name="D435i_camera_back_aluminum">
    <color rgba="0.5 0.5 0.5 1"/>
  </material>
  <!-- camera body, with origin at bottom screw mount -->
  <joint name="D435i_camera_back_joint" type="fixed">
    <origin rpy="0 0.261799 3.141593" xyz="-0.402872 0.0 -0.078218"/>
    <parent link="mobile_base"/>
    <child link="D435i_camera_back_bottom_screw_frame"/>
  </joint>
  <link name="D435i_camera_back_bottom_screw_frame"/>
  <joint name="D435i_camera_back_link_joint" type="fixed">
    <origin rpy="0 0 0" xyz="0 0.0175 0.0125"/>
    <parent link="D435i_camera_back_bottom_screw_frame"/>
    <child link="D435i_camera_back_link"/>
  </joint>
  <link name="D435i_camera_back_link">
    <visual>
      <origin rpy="1.5707963267948966 0 1.5707963267948966" xyz="0.0149 -0.0175 0"/>
      <geometry>
        <!-- <box size="${d435i_cam_width} ${d435i_cam_height} ${d435i_cam_depth}"/> -->
        <mesh filename="package://realsense2_description/meshes/d435.dae"/>
        <!--<mesh filename="package://realsense2_description/meshes/d435/d435.dae"/>-->
      </geometry>
      <material name="D435i_camera_back_aluminum"/>
    </visual>
    <collision>
      <origin rpy="0 0 0" xyz="0 -0.0175 0"/>
      <geometry>
        <box size="0.02505 0.09 0.025"/>
      </geometry>
    </collision>
    <inertial>
      <!-- The following are not reliable values, and should not be used for modeling -->
      <mass value="0.564"/>
      <origin xyz="0 0 0"/>
      <inertia ixx="0.003881243" ixy="0.0" ixz="0.0" iyy="0.000498940" iyz="0.0" izz="0.003879257"/>
    </inertial>
  </link>
  <!-- camera depth joints and links -->
  <joint name="D435i_camera_back_depth_joint" type="fixed">
    <origin rpy="0 0 0" xyz="0 0 0"/>
    <parent link="D435i_camera_back_link"/>
    <child link="D435i_camera_back_depth_frame"/>
  </joint>
  <link name="D435i_camera_back_depth_frame"/>
  <joint name="D435i_camera_back_depth_optical_joint" type="fixed">
    <origin rpy="-1.5707963267948966 0 -1.5707963267948966" xyz="0 0 0"/>
    <parent link="D435i_camera_back_depth_frame"/>
    <child link="D435i_camera_back_depth_optical_frame"/>
  </joint>
  <link name="D435i_camera_back_depth_optical_frame"/>
  <!-- camera left IR joints and links -->
  <joint name="D435i_camera_back_left_ir_joint" type="fixed">
    <origin rpy="0 0 0" xyz="0 0.0 0"/>
    <parent link="D435i_camera_back_depth_frame"/>
    <child link="D435i_camera_back_left_ir_frame"/>
  </joint>
  <link name="D435i_camera_back_left_ir_frame"/>
  <joint name="D435i_camera_back_left_ir_optical_joint" type="fixed">
    <origin rpy="-1.5707963267948966 0 -1.5707963267948966" xyz="0 0 0"/>
    <parent link="D435i_camera_back_left_ir_frame"/>
    <child link="D435i_camera_back_left_ir_optical_frame"/>
  </joint>
  <link name="D435i_camera_back_left_ir_optical_frame"/>
  <!-- camera right IR joints and links -->
  <joint name="D435i_camera_back_right_ir_joint" type="fixed">
    <origin rpy="0 0 0" xyz="0 -0.05 0"/>
    <parent link="D435i_camera_back_depth_frame"/>
    <child link="D435i_camera_back_right_ir_frame"/>
  </joint>
  <link name="D435i_camera_back_right_ir_frame"/>
  <joint name="D435i_camera_back_right_ir_optical_joint" type="fixed">
    <origin rpy="-1.5707963267948966 0 -1.5707963267948966" xyz="0 0 0"/>
    <parent link="D435i_camera_back_right_ir_frame"/>
    <child link="D435i_camera_back_right_ir_optical_frame"/>
  </joint>
  <link name="D435i_camera_back_right_ir_optical_frame"/>
  <!-- camera color joints and links -->
  <joint name="D435i_camera_back_color_joint" type="fixed">
    <origin rpy="0 0 0" xyz="0 0.015 0"/>
    <parent link="D435i_camera_back_depth_frame"/>
    <child link="D435i_camera_back_color_frame"/>
  </joint>
  <link name="D435i_camera_back_color_frame"/>
  <joint name="D435i_camera_back_color_optical_joint" type="fixed">
    <origin rpy="-1.5707963267948966 0 -1.5707963267948966" xyz="0 0 0"/>
    <parent link="D435i_camera_back_color_frame"/>
    <child link="D435i_camera_back_color_optical_frame"/>
  </joint>
  <link name="D435i_camera_back_color_optical_frame"/>
  <!-- camera accel joints and links -->
  <joint name="D435i_camera_back_accel_joint" type="fixed">
    <origin rpy="0 0 0" xyz="-0.00174 0.00552 0.0176"/>
    <parent link="D435i_camera_back_link"/>
    <child link="D435i_camera_back_accel_frame"/>
  </joint>
  <link name="D435i_camera_back_accel_frame"/>
  <joint name="D435i_camera_back_accel_optical_joint" type="fixed">
    <origin rpy="-1.5707963267948966 0 -1.5707963267948966" xyz="0 0 0"/>
    <parent link="D435i_camera_back_accel_frame"/>
    <child link="D435i_camera_back_accel_optical_frame"/>
  </joint>
  <link name="D435i_camera_back_accel_optical_frame"/>
  <!-- camera gyro joints and links -->
  <joint name="D435i_camera_back_gyro_joint" type="fixed">
    <origin rpy="0 0 0" xyz="-0.00174 0.00552 0.0176"/>
    <parent link="D435i_camera_back_link"/>
    <child link="D435i_camera_back_gyro_frame"/>
  </joint>
  <link name="D435i_camera_back_gyro_frame"/>
  <joint name="D435i_camera_back_gyro_optical_joint" type="fixed">
    <origin rpy="-1.5707963267948966 0 -1.5707963267948966" xyz="0 0 0"/>
    <parent link="D435i_camera_back_gyro_frame"/>
    <child link="D435i_camera_back_gyro_optical_frame"/>
  </joint>
  <link name="D435i_camera_back_gyro_optical_frame"/>
  <gazebo reference="D435i_camera_back_link">
    <self_collide>0</self_collide>
    <enable_wind>0</enable_wind>
    <kinematic>0</kinematic>
    <!-- <gravity>1</gravity> -->
    <!--<mu>1</mu>-->
    <mu2>1</mu2>
    <fdir1>0 0 0</fdir1>
    <!--<slip1>0</slip1>
      <slip2>0</slip2>-->
    <kp>1e+13</kp>
    <kd>1</kd>
    <!--<max_vel>0.01</max_vel>
      <min_depth>0</min_depth>-->
    <sensor name="D435i_camera_backcolor" type="camera">
      <camera name="D435i_camera_back">
        <horizontal_fov>1.2112585008840648</horizontal_fov>
        <image>
          <width>1280</width>
          <height>720</height>
          <format>RGB_INT8</format>
        </image>
        <clip>
          <near>0.1</near>
          <far>100</far>
        </clip>
        <noise>
          <type>gaussian</type>
          <mean>0.0</mean>
          <stddev>0.007</stddev>
        </noise>
      </camera>
      <always_on>1</always_on>
      <update_rate>30</update_rate>
      <visualize>True</visualize>
    </sensor>
    <sensor name="D435i_camera_backired1" type="camera">
      <camera name="D435i_camera_back">
        <horizontal_fov>1.4870205226991688</horizontal_fov>
        <image>
          <width>1280</width>
          <height>720</height>
          <format>L_INT8</format>
        </image>
        <clip>
          <near>0.1</near>
          <far>100</far>
        </clip>
        <noise>
          <type>gaussian</type>
          <mean>0.0</mean>
          <stddev>0.05</stddev>
        </noise>
      </camera>
      <always_on>1</always_on>
      <update_rate>90</update_rate>
      <visualize>false</visualize>
    </sensor>
    <sensor name="D435i_camera_backired2" type="camera">
      <camera name="D435i_camera_back">
        <horizontal_fov>1.4870205226991688</horizontal_fov>
        <image>
          <width>1280</width>
          <height>720</height>
          <format>L_INT8</format>
        </image>
        <clip>
          <near>0.1</near>
          <far>100</far>
        </clip>
        <noise>
          <type>gaussian</type>
          <mean>0.0</mean>
          <stddev>0.05</stddev>
        </noise>
      </camera>
      <always_on>1</always_on>
      <update_rate>90</update_rate>
      <visualize>false</visualize>
    </sensor>
    <sensor name="D435i_camera_backdepth" type="depth">
      <camera name="D435i_camera_back">
        <horizontal_fov>1.2112585008840648</horizontal_fov>
        <image>
          <width>1280</width>
          <height>720</height>
        </image>
        <clip>
          <near>0.1</near>
          <far>100</far>
        </clip>
        <noise>
          <type>gaussian</type>
          <mean>0.0</mean>
          <stddev>0.100</stddev>
        </noise>
      </camera>
      <always_on>1</always_on>
      <update_rate>30</update_rate>
      <visualize>false</visualize>
    </sensor>
    <sensor name="D435i_camera_backaccel" type="imu">
      <always_on>true</always_on>
      <update_rate>300</update_rate>
      <topic>D435i_camera_back/accel/sample</topic>
      <plugin filename="librealsense_gazebo_accel_sensor.so" name="D435i_camera_back_accel_plugin">
        <topicName>D435i_camera_back/accel/sample</topicName>
        <bodyName>D435i_camera_back_link</bodyName>
        <updateRateHZ>300</updateRateHZ>
        <gaussianNoise>0.1</gaussianNoise>
        <xyzOffset>0 0 0</xyzOffset>
        <rpyOffset>0 0 0</rpyOffset>
        <frameName>D435i_camera_back_accel_optical_frame</frameName>
        <initialOrientationAsReference>false</initialOrientationAsReference>
      </plugin>
      <pose>0 0 0 0 0 0</pose>
    </sensor>
    <sensor name="D435i_camera_backgyro" type="imu">
      <always_on>true</always_on>
      <update_rate>300</update_rate>
      <topic>D435i_camera_back/gyro/sample</topic>
      <plugin filename="librealsense_gazebo_gyro_sensor.so" name="D435i_camera_back_gyro_plugin">
        <topicName>D435i_camera_back/gyro/sample</topicName>
        <bodyName>D435i_camera_back_link</bodyName>
        <updateRateHZ>300</updateRateHZ>
        <gaussianNoise>0.1</gaussianNoise>
        <xyzOffset>0 0 0</xyzOffset>
        <rpyOffset>0 0 0</rpyOffset>
        <frameName>D435i_camera_back_gyro_optical_frame</frameName>
        <initialOrientationAsReference>false</initialOrientationAsReference>
      </plugin>
    </sensor>
  </gazebo>
  <gazebo>
    <plugin filename="librealsense_gazebo_plugin.so" name="D435i_camera_back">
      <prefix>D435i_camera_back</prefix>
      <!-- Color camera settings -->
      <colorUpdateRate>30</colorUpdateRate>
      <colorTopicName>color/image_raw</colorTopicName>
      <colorOpticalframeName>D435i_camera_back_color_optical_frame</colorOpticalframeName>
      <colorCameraInfoTopicName>color/camera_info</colorCameraInfoTopicName>
      <!-- Infrared camera settings -->
      <infraredUpdateRate>90</infraredUpdateRate>
      <infrared1TopicName>infra1/image_rect_raw</infrared1TopicName>
      <infrared2TopicName>infra2/image_rect_raw</infrared2TopicName>
      <infrared1CameraInfoTopicName>infra1/camera_info</infrared1CameraInfoTopicName>
      <infrared2CameraInfoTopicName>infra2/camera_info</infrared2CameraInfoTopicName>
      <infrared1OpticalframeName>D435i_camera_back_left_ir_optical_frame</infrared1OpticalframeName>
      <infrared2OpticalframeName>D435i_camera_back_right_ir_optical_frame</infrared2OpticalframeName>
      <!-- Depth camera settings -->
      <rangeMinDepth>0.2</rangeMinDepth>
      <rangeMaxDepth>10.0</rangeMaxDepth>
      <depthUpdateRate>30</depthUpdateRate>
      <depthTopicName>aligned_depth_to_color/image_raw</depthTopicName>
      <depthCameraInfoTopicName>aligned_depth_to_color/camera_info</depthCameraInfoTopicName>
      <depthOpticalframeName>D435i_camera_back_color_optical_frame</depthOpticalframeName>
      <!-- Pointlcloud settings -->
      <pointCloud>True</pointCloud>
      <pointCloudTopicName>depth/color/points</pointCloudTopicName>
      <pointCloudCutoff>0.5</pointCloudCutoff>
    </plugin>
  </gazebo>
  <material name="T265_camera_left_aluminum">
    <color rgba="0.5 0.5 0.5 1"/>
  </material>
  <!-- camera body, with origin at camera_pose_frame -->
  <joint name="T265_camera_left_pose_joint" type="fixed">
    <origin rpy="3.141593 0.0 1.570796" xyz="0.02375 0.37245 -0.062"/>
    <parent link="mobile_base"/>
    <child link="T265_camera_left_pose_frame"/>
  </joint>
  <link name="T265_camera_left_pose_frame">
    <visual>
      <origin rpy="1.5707963267948966 0 1.5707963267948966" xyz="0 0 0"/>
      <geometry>
        <mesh filename="package://realsense_gazebo_description/meshes/t265_full.stl" scale="0.001 0.001 0.001"/>
      </geometry>
      <material name="T265_camera_left_aluminum"/>
    </visual>
    <collision>
      <origin rpy="1.5707963267948966 0 1.5707963267948966" xyz="0 0 0"/>
      <geometry>
        <mesh filename="package://realsense_gazebo_description/meshes/t265_simplified.stl" scale="0.001 0.001 0.001"/>
      </geometry>
    </collision>
    <inertial>
      <!-- The following are not reliable values, and should not be used for modeling -->
      <mass value="0.068024"/>
      <origin xyz="0 0 0"/>
      <inertia ixx="0.0000039782" ixy="0.0" ixz="0.000000034641" iyy="0.000065045" iyz="0.0" izz="0.000067499"/>
    </inertial>
  </link>
  <!-- camera body, with origin at camera_link -->
  <joint name="T265_camera_left_link_joint" type="fixed">
    <origin rpy="1.5707963267948966 0 -1.5707963267948966" xyz="0 0 0"/>
    <parent link="T265_camera_left_pose_frame"/>
    <child link="T265_camera_left_link"/>
  </joint>
  <link name="T265_camera_left_link"/>
  <joint name="T265_camera_left_fisheye1_rgb_joint" type="fixed">
    <origin rpy="0 1.5707963267948966 1.5707963267948966" xyz="-0.0411 0.0 0.0"/>
    <parent link="T265_camera_left_link"/>
    <child link="T265_camera_left_fisheye1_rgb_frame"/>
  </joint>
  <link name="T265_camera_left_fisheye1_rgb_frame"/>
  <joint name="T265_camera_left_fisheye2_rgb_joint" type="fixed">
    <origin rpy="0 1.5707963267948966 1.5707963267948966" xyz="0.0229 0.0 0.0"/>
    <parent link="T265_camera_left_link"/>
    <child link="T265_camera_left_fisheye2_rgb_frame"/>
  </joint>
  <link name="T265_camera_left_fisheye2_rgb_frame"/>
  <joint name="T265_camera_left_fisheye1_optical_joint" type="fixed">
    <origin rpy="-1.5707963267948966 0 -1.5707963267948966" xyz="0 0 0"/>
    <parent link="T265_camera_left_fisheye1_rgb_frame"/>
    <child link="T265_camera_left_fisheye1_optical_frame"/>
  </joint>
  <link name="T265_camera_left_fisheye1_optical_frame"/>
  <joint name="T265_camera_left_fisheye2_optical_joint" type="fixed">
    <origin rpy="-1.5707963267948966 0 -1.5707963267948966" xyz="0 0 0"/>
    <parent link="T265_camera_left_fisheye2_rgb_frame"/>
    <child link="T265_camera_left_fisheye2_optical_frame"/>
  </joint>
  <link name="T265_camera_left_fisheye2_optical_frame"/>
  <!-- IMU joints and links -->
  <joint name="T265_camera_left_accel_joint" type="fixed">
    <origin rpy="0 3.141592653589793 0" xyz="-0.0311 0 0.00655"/>
    <parent link="T265_camera_left_link"/>
    <child link="T265_camera_left_accel_frame"/>
  </joint>
  <link name="T265_camera_left_accel_frame"/>
  <joint name="T265_camera_left_accel_optical_joint" type="fixed">
    <origin rpy="0 3.141592653589793 0" xyz="-0.0311 0 0.00655"/>
    <parent link="T265_camera_left_accel_frame"/>
    <child link="T265_camera_left_accel_optical_frame"/>
  </joint>
  <link name="T265_camera_left_accel_optical_frame"/>
  <joint name="T265_camera_left_gyro_joint" type="fixed">
    <origin rpy="0 3.141592653589793 0" xyz="-0.0311 0 0.00655"/>
    <parent link="T265_camera_left_link"/>
    <child link="T265_camera_left_gyro_frame"/>
  </joint>
  <link name="T265_camera_left_gyro_frame"/>
  <joint name="T265_camera_left_gyro_optical_joint" type="fixed">
    <origin rpy="0 0 0" xyz="0 0 0"/>
    <parent link="T265_camera_left_gyro_frame"/>
    <child link="T265_camera_left_gyro_optical_frame"/>
  </joint>
  <link name="T265_camera_left_gyro_optical_frame"/>
  <!-- Load parameters to model's main link-->
  <gazebo reference="T265_camera_left_fisheye1_rgb_frame">
    <self_collide>0</self_collide>
    <enable_wind>0</enable_wind>
    <kinematic>0</kinematic>
    <!-- <gravity>1</gravity> -->
    <!--<mu>1</mu>-->
    <mu2>1</mu2>
    <fdir1>0 0 0</fdir1>
    <!--<slip1>0</slip1>
      <slip2>0</slip2>-->
    <kp>1e+13</kp>
    <kd>1</kd>
    <!--<max_vel>0.01</max_vel>
      <min_depth>0</min_depth>-->
    <sensor name="T265_camera_leftfisheye1" type="wideanglecamera">
      <!-- <origin xyz="0 0 0" rpy="0 ${M_PI/2} 0"/> -->
      <update_rate>30</update_rate>
      <camera>
        <horizontal_fov>1.95</horizontal_fov>
        <image>
          <width>848</width>
          <height>800</height>
        </image>
        <clip>
          <near>0.2</near>
          <far>100</far>
        </clip>
        <lens>
          <!-- type element is mandatory -->
          <type>orthographic</type>
          <!-- if it is set to `true` your horizontal FOV will remain as defined -->
          <!-- othervise it depends on lens type and custom function, if there is one -->
          <scale_to_hfov>true</scale_to_hfov>
          <!-- clip everything that is outside of this angle -->
          <!-- eye balled value for these cameras-->
          <cutoff_angle>2.20</cutoff_angle>
          <!-- resolution of the cubemap texture, the highter it is - the sharper is your image -->
          <env_texture_size>1024</env_texture_size>
        </lens>
      </camera>
      <plugin filename="libgazebo_ros_camera.so" name="T265_camera_leftfisheye1">
        <alwaysOn>true</alwaysOn>
        <updateRate>30</updateRate>
        <cameraName>T265_camera_left/fisheye1</cameraName>
        <imageTopicName>image_raw</imageTopicName>
        <cameraInfoTopicName>camera_info</cameraInfoTopicName>
        <frameName>T265_camera_left_fisheye1_optical_frame</frameName>
        <hackBaseline>0.07</hackBaseline>
        <distortionK1>-0.00040996368625201285</distortionK1>
        <distortionK2>0.03653175011277199</distortionK2>
        <distortionK3>0.0</distortionK3>
        <distortionP1>-0.034823670983314514</distortionP1>
        <distortionP2>0.0052825710736215115</distortionP2>
        <Cx>416.22</Cx>
        <Cy>402.1</Cy>
        <CxPrime>416.22</CxPrime>
      </plugin>
    </sensor>
  </gazebo>
  <gazebo reference="T265_camera_left_fisheye2_rgb_frame">
    <self_collide>0</self_collide>
    <enable_wind>0</enable_wind>
    <kinematic>0</kinematic>
    <!-- <gravity>1</gravity> -->
    <!--<mu>1</mu>-->
    <mu2>1</mu2>
    <fdir1>0 0 0</fdir1>
    <!--<slip1>0</slip1>
      <slip2>0</slip2>-->
    <kp>1e+13</kp>
    <kd>1</kd>
    <!--<max_vel>0.01</max_vel>
      <min_depth>0</min_depth>-->
    <sensor name="T265_camera_leftfisheye2" type="wideanglecamera">
      <!-- <origin xyz="0 0 0" rpy="0 ${M_PI/2} 0"/> -->
      <update_rate>30</update_rate>
      <camera>
        <horizontal_fov>2.84</horizontal_fov>
        <image>
          <width>848</width>
          <height>800</height>
        </image>
        <clip>
          <near>0.1</near>
          <far>100</far>
        </clip>
        <lens>
          <!-- type element is mandatory -->
          <type>orthographic</type>
          <!-- if it is set to `true` your horizontal FOV will remain as defined -->
          <!-- othervise it depends on lens type and custom function, if there is one -->
          <scale_to_hfov>true</scale_to_hfov>
          <!-- clip everything that is outside of this angle -->
          <!-- eye balled value for these cameras-->
          <cutoff_angle>2.20</cutoff_angle>
          <!-- resolution of the cubemap texture, the highter it is - the sharper is your image -->
          <env_texture_size>1024</env_texture_size>
        </lens>
      </camera>
      <always_on>1</always_on>
      <plugin filename="libgazebo_ros_camera.so" name="T265_camera_leftfisheye2">
        <alwaysOn>true</alwaysOn>
        <updateRate>30</updateRate>
        <cameraName>T265_camera_left/fisheye2</cameraName>
        <imageTopicName>image_raw</imageTopicName>
        <cameraInfoTopicName>camera_info</cameraInfoTopicName>
        <frameName>T265_camera_left_fisheye2_optical_frame</frameName>
        <hackBaseline>0.07</hackBaseline>
        <distortionK1>-0.00040996368625201285</distortionK1>
        <distortionK2>0.03653175011277199</distortionK2>
        <distortionK3>0.0</distortionK3>
        <distortionP1>-0.034823670983314514</distortionP1>
        <distortionP2>0.0052825710736215115</distortionP2>
      </plugin>
    </sensor>
    <sensor name="T265_camera_leftaccel" type="imu">
      <always_on>true</always_on>
      <update_rate>62.5</update_rate>
      <plugin filename="librealsense_gazebo_accel_sensor.so" name="T265_camera_left_accel_plugin">
        <topicName>T265_camera_left/accel/sample</topicName>
        <bodyName>T265_camera_left_pose_frame</bodyName>
        <updateRateHZ>62.5</updateRateHZ>
        <gaussianNoise>0.1</gaussianNoise>
        <xyzOffset>0 0 0</xyzOffset>
        <rpyOffset>0 0 0</rpyOffset>
        <frameName>T265_camera_left_accel_optical_frame</frameName>
        <initialOrientationAsReference>false</initialOrientationAsReference>
      </plugin>
      <pose>0 0 0 0 0 0</pose>
    </sensor>
    <sensor name="T265_camera_leftgyro" type="imu">
      <always_on>true</always_on>
      <update_rate>200</update_rate>
      <topic>T265_camera_left/gyro/sample</topic>
      <plugin filename="librealsense_gazebo_gyro_sensor.so" name="T265_camera_left_gyro_plugin">
        <topicName>T265_camera_left/gyro/sample</topicName>
        <bodyName>T265_camera_left_pose_frame</bodyName>
        <updateRateHZ>200</updateRateHZ>
        <gaussianNoise>0.1</gaussianNoise>
        <xyzOffset>0 0 0</xyzOffset>
        <rpyOffset>0 0 0</rpyOffset>
        <frameName>T265_camera_left_gyro_optical_frame</frameName>
        <initialOrientationAsReference>false</initialOrientationAsReference>
      </plugin>
    </sensor>
  </gazebo>
  <gazebo>
    <!-- Odom from SLAM -->
    <plugin filename="libgazebo_ros_p3d.so" name="p3d_base_controller">
      <alwaysOn>true</alwaysOn>
      <updateRate>262</updateRate>
      <bodyName>T265_camera_left_pose_frame</bodyName>
      <topicName>T265_camera_left/odom/sample</topicName>
      <gaussianNoise>0.01</gaussianNoise>
      <frameName>world</frameName>
      <xyzOffsets>0.0 0.0 0.25</xyzOffsets>
      <rpyOffsets>0.0 0.0 0.0</rpyOffsets>
    </plugin>
  </gazebo>
  <material name="T265_camera_right_aluminum">
    <color rgba="0.5 0.5 0.5 1"/>
  </material>
  <!-- camera body, with origin at camera_pose_frame -->
  <joint name="T265_camera_right_pose_joint" type="fixed">
    <origin rpy="0 0.0 -1.570796" xyz="0.02375 -0.37245 -0.062"/>
    <parent link="mobile_base"/>
    <child link="T265_camera_right_pose_frame"/>
  </joint>
  <link name="T265_camera_right_pose_frame">
    <visual>
      <origin rpy="1.5707963267948966 0 1.5707963267948966" xyz="0 0 0"/>
      <geometry>
        <mesh filename="package://realsense_gazebo_description/meshes/t265_full.stl" scale="0.001 0.001 0.001"/>
      </geometry>
      <material name="T265_camera_right_aluminum"/>
    </visual>
    <collision>
      <origin rpy="1.5707963267948966 0 1.5707963267948966" xyz="0 0 0"/>
      <geometry>
        <mesh filename="package://realsense_gazebo_description/meshes/t265_simplified.stl" scale="0.001 0.001 0.001"/>
      </geometry>
    </collision>
    <inertial>
      <!-- The following are not reliable values, and should not be used for modeling -->
      <mass value="0.068024"/>
      <origin xyz="0 0 0"/>
      <inertia ixx="0.0000039782" ixy="0.0" ixz="0.000000034641" iyy="0.000065045" iyz="0.0" izz="0.000067499"/>
    </inertial>
  </link>
  <!-- camera body, with origin at camera_link -->
  <joint name="T265_camera_right_link_joint" type="fixed">
    <origin rpy="1.5707963267948966 0 -1.5707963267948966" xyz="0 0 0"/>
    <parent link="T265_camera_right_pose_frame"/>
    <child link="T265_camera_right_link"/>
  </joint>
  <link name="T265_camera_right_link"/>
  <joint name="T265_camera_right_fisheye1_rgb_joint" type="fixed">
    <origin rpy="0 1.5707963267948966 1.5707963267948966" xyz="-0.0411 0.0 0.0"/>
    <parent link="T265_camera_right_link"/>
    <child link="T265_camera_right_fisheye1_rgb_frame"/>
  </joint>
  <link name="T265_camera_right_fisheye1_rgb_frame"/>
  <joint name="T265_camera_right_fisheye2_rgb_joint" type="fixed">
    <origin rpy="0 1.5707963267948966 1.5707963267948966" xyz="0.0229 0.0 0.0"/>
    <parent link="T265_camera_right_link"/>
    <child link="T265_camera_right_fisheye2_rgb_frame"/>
  </joint>
  <link name="T265_camera_right_fisheye2_rgb_frame"/>
  <joint name="T265_camera_right_fisheye1_optical_joint" type="fixed">
    <origin rpy="-1.5707963267948966 0 -1.5707963267948966" xyz="0 0 0"/>
    <parent link="T265_camera_right_fisheye1_rgb_frame"/>
    <child link="T265_camera_right_fisheye1_optical_frame"/>
  </joint>
  <link name="T265_camera_right_fisheye1_optical_frame"/>
  <joint name="T265_camera_right_fisheye2_optical_joint" type="fixed">
    <origin rpy="-1.5707963267948966 0 -1.5707963267948966" xyz="0 0 0"/>
    <parent link="T265_camera_right_fisheye2_rgb_frame"/>
    <child link="T265_camera_right_fisheye2_optical_frame"/>
  </joint>
  <link name="T265_camera_right_fisheye2_optical_frame"/>
  <!-- IMU joints and links -->
  <joint name="T265_camera_right_accel_joint" type="fixed">
    <origin rpy="0 3.141592653589793 0" xyz="-0.0311 0 0.00655"/>
    <parent link="T265_camera_right_link"/>
    <child link="T265_camera_right_accel_frame"/>
  </joint>
  <link name="T265_camera_right_accel_frame"/>
  <joint name="T265_camera_right_accel_optical_joint" type="fixed">
    <origin rpy="0 3.141592653589793 0" xyz="-0.0311 0 0.00655"/>
    <parent link="T265_camera_right_accel_frame"/>
    <child link="T265_camera_right_accel_optical_frame"/>
  </joint>
  <link name="T265_camera_right_accel_optical_frame"/>
  <joint name="T265_camera_right_gyro_joint" type="fixed">
    <origin rpy="0 3.141592653589793 0" xyz="-0.0311 0 0.00655"/>
    <parent link="T265_camera_right_link"/>
    <child link="T265_camera_right_gyro_frame"/>
  </joint>
  <link name="T265_camera_right_gyro_frame"/>
  <joint name="T265_camera_right_gyro_optical_joint" type="fixed">
    <origin rpy="0 0 0" xyz="0 0 0"/>
    <parent link="T265_camera_right_gyro_frame"/>
    <child link="T265_camera_right_gyro_optical_frame"/>
  </joint>
  <link name="T265_camera_right_gyro_optical_frame"/>
  <!-- Load parameters to model's main link-->
  <gazebo reference="T265_camera_right_fisheye1_rgb_frame">
    <self_collide>0</self_collide>
    <enable_wind>0</enable_wind>
    <kinematic>0</kinematic>
    <!-- <gravity>1</gravity> -->
    <!--<mu>1</mu>-->
    <mu2>1</mu2>
    <fdir1>0 0 0</fdir1>
    <!--<slip1>0</slip1>
      <slip2>0</slip2>-->
    <kp>1e+13</kp>
    <kd>1</kd>
    <!--<max_vel>0.01</max_vel>
      <min_depth>0</min_depth>-->
    <sensor name="T265_camera_rightfisheye1" type="wideanglecamera">
      <!-- <origin xyz="0 0 0" rpy="0 ${M_PI/2} 0"/> -->
      <update_rate>30</update_rate>
      <camera>
        <horizontal_fov>1.95</horizontal_fov>
        <image>
          <width>848</width>
          <height>800</height>
        </image>
        <clip>
          <near>0.2</near>
          <far>100</far>
        </clip>
        <lens>
          <!-- type element is mandatory -->
          <type>orthographic</type>
          <!-- if it is set to `true` your horizontal FOV will remain as defined -->
          <!-- othervise it depends on lens type and custom function, if there is one -->
          <scale_to_hfov>true</scale_to_hfov>
          <!-- clip everything that is outside of this angle -->
          <!-- eye balled value for these cameras-->
          <cutoff_angle>2.20</cutoff_angle>
          <!-- resolution of the cubemap texture, the highter it is - the sharper is your image -->
          <env_texture_size>1024</env_texture_size>
        </lens>
      </camera>
      <plugin filename="libgazebo_ros_camera.so" name="T265_camera_rightfisheye1">
        <alwaysOn>true</alwaysOn>
        <updateRate>30</updateRate>
        <cameraName>T265_camera_right/fisheye1</cameraName>
        <imageTopicName>image_raw</imageTopicName>
        <cameraInfoTopicName>camera_info</cameraInfoTopicName>
        <frameName>T265_camera_right_fisheye1_optical_frame</frameName>
        <hackBaseline>0.07</hackBaseline>
        <distortionK1>-0.00040996368625201285</distortionK1>
        <distortionK2>0.03653175011277199</distortionK2>
        <distortionK3>0.0</distortionK3>
        <distortionP1>-0.034823670983314514</distortionP1>
        <distortionP2>0.0052825710736215115</distortionP2>
        <Cx>416.22</Cx>
        <Cy>402.1</Cy>
        <CxPrime>416.22</CxPrime>
      </plugin>
    </sensor>
  </gazebo>
  <gazebo reference="T265_camera_right_fisheye2_rgb_frame">
    <self_collide>0</self_collide>
    <enable_wind>0</enable_wind>
    <kinematic>0</kinematic>
    <!-- <gravity>1</gravity> -->
    <!--<mu>1</mu>-->
    <mu2>1</mu2>
    <fdir1>0 0 0</fdir1>
    <!--<slip1>0</slip1>
      <slip2>0</slip2>-->
    <kp>1e+13</kp>
    <kd>1</kd>
    <!--<max_vel>0.01</max_vel>
      <min_depth>0</min_depth>-->
    <sensor name="T265_camera_rightfisheye2" type="wideanglecamera">
      <!-- <origin xyz="0 0 0" rpy="0 ${M_PI/2} 0"/> -->
      <update_rate>30</update_rate>
      <camera>
        <horizontal_fov>2.84</horizontal_fov>
        <image>
          <width>848</width>
          <height>800</height>
        </image>
        <clip>
          <near>0.1</near>
          <far>100</far>
        </clip>
        <lens>
          <!-- type element is mandatory -->
          <type>orthographic</type>
          <!-- if it is set to `true` your horizontal FOV will remain as defined -->
          <!-- othervise it depends on lens type and custom function, if there is one -->
          <scale_to_hfov>true</scale_to_hfov>
          <!-- clip everything that is outside of this angle -->
          <!-- eye balled value for these cameras-->
          <cutoff_angle>2.20</cutoff_angle>
          <!-- resolution of the cubemap texture, the highter it is - the sharper is your image -->
          <env_texture_size>1024</env_texture_size>
        </lens>
      </camera>
      <always_on>1</always_on>
      <plugin filename="libgazebo_ros_camera.so" name="T265_camera_rightfisheye2">
        <alwaysOn>true</alwaysOn>
        <updateRate>30</updateRate>
        <cameraName>T265_camera_right/fisheye2</cameraName>
        <imageTopicName>image_raw</imageTopicName>
        <cameraInfoTopicName>camera_info</cameraInfoTopicName>
        <frameName>T265_camera_right_fisheye2_optical_frame</frameName>
        <hackBaseline>0.07</hackBaseline>
        <distortionK1>-0.00040996368625201285</distortionK1>
        <distortionK2>0.03653175011277199</distortionK2>
        <distortionK3>0.0</distortionK3>
        <distortionP1>-0.034823670983314514</distortionP1>
        <distortionP2>0.0052825710736215115</distortionP2>
      </plugin>
    </sensor>
    <sensor name="T265_camera_rightaccel" type="imu">
      <always_on>true</always_on>
      <update_rate>62.5</update_rate>
      <plugin filename="librealsense_gazebo_accel_sensor.so" name="T265_camera_right_accel_plugin">
        <topicName>T265_camera_right/accel/sample</topicName>
        <bodyName>T265_camera_right_pose_frame</bodyName>
        <updateRateHZ>62.5</updateRateHZ>
        <gaussianNoise>0.1</gaussianNoise>
        <xyzOffset>0 0 0</xyzOffset>
        <rpyOffset>0 0 0</rpyOffset>
        <frameName>T265_camera_right_accel_optical_frame</frameName>
        <initialOrientationAsReference>false</initialOrientationAsReference>
      </plugin>
      <pose>0 0 0 0 0 0</pose>
    </sensor>
    <sensor name="T265_camera_rightgyro" type="imu">
      <always_on>true</always_on>
      <update_rate>200</update_rate>
      <topic>T265_camera_right/gyro/sample</topic>
      <plugin filename="librealsense_gazebo_gyro_sensor.so" name="T265_camera_right_gyro_plugin">
        <topicName>T265_camera_right/gyro/sample</topicName>
        <bodyName>T265_camera_right_pose_frame</bodyName>
        <updateRateHZ>200</updateRateHZ>
        <gaussianNoise>0.1</gaussianNoise>
        <xyzOffset>0 0 0</xyzOffset>
        <rpyOffset>0 0 0</rpyOffset>
        <frameName>T265_camera_right_gyro_optical_frame</frameName>
        <initialOrientationAsReference>false</initialOrientationAsReference>
      </plugin>
    </sensor>
  </gazebo>
  <gazebo>
    <!-- Odom from SLAM -->
    <plugin filename="libgazebo_ros_p3d.so" name="p3d_base_controller">
      <alwaysOn>true</alwaysOn>
      <updateRate>262</updateRate>
      <bodyName>T265_camera_right_pose_frame</bodyName>
      <topicName>T265_camera_right/odom/sample</topicName>
      <gaussianNoise>0.01</gaussianNoise>
      <frameName>world</frameName>
      <xyzOffsets>0.0 0.0 0.25</xyzOffsets>
      <rpyOffsets>0.0 0.0 0.0</rpyOffsets>
    </plugin>
  </gazebo>
  <joint name="front_base_base_mount_joint" type="fixed">
    <origin rpy="0.0 0.0 0.0" xyz="0.5305 0.315 -0.1"/>
    <parent link="mobile_base"/>
    <child link="front_base_base_link"/>
  </joint>
  <link name="front_base_base_link">
    <inertial>
      <mass value="0.83"/>
      <origin xyz="0 0 0.03585"/>
      <inertia ixx="0.000908059425" ixy="0" ixz="0" iyy="0.000908059425" iyz="0" izz="0.0011049624"/>
    </inertial>
    <visual>
      <geometry>
        <mesh filename="package://velodyne_description/meshes/VLP16_base_1.dae"/>
      </geometry>
    </visual>
    <visual>
      <geometry>
        <mesh filename="package://velodyne_description/meshes/VLP16_base_2.dae"/>
      </geometry>
    </visual>
    <collision>
      <origin rpy="0 0 0" xyz="0 0 0.03585"/>
      <geometry>
        <cylinder length="0.0717" radius="0.0516"/>
      </geometry>
    </collision>
  </link>
  <joint name="front_base_base_scan_joint" type="fixed">
    <origin rpy="0 0 0" xyz="0 0 0.0377"/>
    <parent link="front_base_base_link"/>
    <child link="front_base"/>
  </joint>
  <link name="front_base">
    <inertial>
      <mass value="0.01"/>
      <origin xyz="0 0 0"/>
      <inertia ixx="1e-7" ixy="0" ixz="0" iyy="1e-7" iyz="0" izz="1e-7"/>
    </inertial>
    <visual>
      <origin xyz="0 0 -0.0377"/>
      <geometry>
        <mesh filename="package://velodyne_description/meshes/VLP16_scan.dae"/>
      </geometry>
    </visual>
    <collision>
      <geometry>
        <sphere radius="0"/>
      </geometry>
    </collision>
  </link>
  <!-- Gazebo requires the velodyne_gazebo_plugins package -->
  <gazebo reference="front_base">
    <sensor name="front_base-VLP16" type="gpu_ray">
      <pose>0 0 0 0 0 0</pose>
      <visualize>false</visualize>
      <update_rate>10</update_rate>
      <ray>
        <scan>
          <horizontal>
            <samples>440</samples>
            <resolution>1</resolution>
            <min_angle>-3.141592653589793</min_angle>
            <max_angle>3.141592653589793</max_angle>
          </horizontal>
          <vertical>
            <samples>16</samples>
            <resolution>1</resolution>
            <min_angle>-0.2617993877991494</min_angle>
            <max_angle> 0.2617993877991494</max_angle>
          </vertical>
        </scan>
        <range>
          <min>0.3</min>
          <max>131.0</max>
          <resolution>0.001</resolution>
        </range>
        <noise>
          <type>gaussian</type>
          <mean>0.0</mean>
          <stddev>0.0</stddev>
        </noise>
      </ray>
      <plugin filename="libgazebo_ros_velodyne_gpu_laser.so" name="gazebo_ros_laser_controller">
        <topicName>/front_base/velodyne_points</topicName>
        <frameName>front_base</frameName>
        <organize_cloud>False</organize_cloud>
        <min_range>0.9</min_range>
        <max_range>130.0</max_range>
        <gaussianNoise>0.008</gaussianNoise>
      </plugin>
    </sensor>
  </gazebo>
  <joint name="back_base_base_mount_joint" type="fixed">
    <origin rpy="0.0 0.0 3.141593" xyz="-0.5305 -0.315 -0.1"/>
    <parent link="mobile_base"/>
    <child link="back_base_base_link"/>
  </joint>
  <link name="back_base_base_link">
    <inertial>
      <mass value="0.83"/>
      <origin xyz="0 0 0.03585"/>
      <inertia ixx="0.000908059425" ixy="0" ixz="0" iyy="0.000908059425" iyz="0" izz="0.0011049624"/>
    </inertial>
    <visual>
      <geometry>
        <mesh filename="package://velodyne_description/meshes/VLP16_base_1.dae"/>
      </geometry>
    </visual>
    <visual>
      <geometry>
        <mesh filename="package://velodyne_description/meshes/VLP16_base_2.dae"/>
      </geometry>
    </visual>
    <collision>
      <origin rpy="0 0 0" xyz="0 0 0.03585"/>
      <geometry>
        <cylinder length="0.0717" radius="0.0516"/>
      </geometry>
    </collision>
  </link>
  <joint name="back_base_base_scan_joint" type="fixed">
    <origin rpy="0 0 0" xyz="0 0 0.0377"/>
    <parent link="back_base_base_link"/>
    <child link="back_base"/>
  </joint>
  <link name="back_base">
    <inertial>
      <mass value="0.01"/>
      <origin xyz="0 0 0"/>
      <inertia ixx="1e-7" ixy="0" ixz="0" iyy="1e-7" iyz="0" izz="1e-7"/>
    </inertial>
    <visual>
      <origin xyz="0 0 -0.0377"/>
      <geometry>
        <mesh filename="package://velodyne_description/meshes/VLP16_scan.dae"/>
      </geometry>
    </visual>
    <collision>
      <geometry>
        <sphere radius="0"/>
      </geometry>
    </collision>
  </link>
  <!-- Gazebo requires the velodyne_gazebo_plugins package -->
  <gazebo reference="back_base">
    <sensor name="back_base-VLP16" type="gpu_ray">
      <pose>0 0 0 0 0 0</pose>
      <visualize>false</visualize>
      <update_rate>10</update_rate>
      <ray>
        <scan>
          <horizontal>
            <samples>440</samples>
            <resolution>1</resolution>
            <min_angle>-3.141592653589793</min_angle>
            <max_angle>3.141592653589793</max_angle>
          </horizontal>
          <vertical>
            <samples>16</samples>
            <resolution>1</resolution>
            <min_angle>-0.2617993877991494</min_angle>
            <max_angle> 0.2617993877991494</max_angle>
          </vertical>
        </scan>
        <range>
          <min>0.3</min>
          <max>131.0</max>
          <resolution>0.001</resolution>
        </range>
        <noise>
          <type>gaussian</type>
          <mean>0.0</mean>
          <stddev>0.0</stddev>
        </noise>
      </ray>
      <plugin filename="libgazebo_ros_velodyne_gpu_laser.so" name="gazebo_ros_laser_controller">
        <topicName>/back_base/velodyne_points</topicName>
        <frameName>back_base</frameName>
        <organize_cloud>False</organize_cloud>
        <min_range>0.9</min_range>
        <max_range>130.0</max_range>
        <gaussianNoise>0.008</gaussianNoise>
      </plugin>
    </sensor>
  </gazebo>
  <joint name="ultrasound_fl_sag_base_mount_joint" type="fixed">
    <origin rpy="0.0 1.963496 0.0" xyz="0.5105 0.315 -0.129"/>
    <parent link="mobile_base"/>
    <child link="ultrasound_fl_sag_base_link"/>
  </joint>
  <link name="ultrasound_fl_sag_base_link"/>
  <!-- Rotate sensor frame (readings are on x axis instead of z) -->
  <joint name="ultrasound_fl_sag_joint" type="fixed">
    <origin rpy="0.0 -1.57 0.0" xyz="0 0 0"/>
    <parent link="ultrasound_fl_sag_base_link"/>
    <child link="ultrasound_fl_sag"/>
  </joint>
  <link name="ultrasound_fl_sag"/>
  <joint name="ultrasound_fr_sag_base_mount_joint" type="fixed">
    <origin rpy="0.0 1.963496 0.0" xyz="0.5105 -0.315 -0.129"/>
    <parent link="mobile_base"/>
    <child link="ultrasound_fr_sag_base_link"/>
  </joint>
  <link name="ultrasound_fr_sag_base_link"/>
  <!-- Rotate sensor frame (readings are on x axis instead of z) -->
  <joint name="ultrasound_fr_sag_joint" type="fixed">
    <origin rpy="0.0 -1.57 0.0" xyz="0 0 0"/>
    <parent link="ultrasound_fr_sag_base_link"/>
    <child link="ultrasound_fr_sag"/>
  </joint>
  <link name="ultrasound_fr_sag"/>
  <joint name="ultrasound_rl_sag_base_mount_joint" type="fixed">
    <origin rpy="0.0 1.963496 3.141593" xyz="-0.5105 0.315 -0.129"/>
    <parent link="mobile_base"/>
    <child link="ultrasound_rl_sag_base_link"/>
  </joint>
  <link name="ultrasound_rl_sag_base_link"/>
  <!-- Rotate sensor frame (readings are on x axis instead of z) -->
  <joint name="ultrasound_rl_sag_joint" type="fixed">
    <origin rpy="0.0 -1.57 0.0" xyz="0 0 0"/>
    <parent link="ultrasound_rl_sag_base_link"/>
    <child link="ultrasound_rl_sag"/>
  </joint>
  <link name="ultrasound_rl_sag"/>
  <joint name="ultrasound_rr_sag_base_mount_joint" type="fixed">
    <origin rpy="0.0 1.963496 3.141593" xyz="-0.5105 -0.315 -0.129"/>
    <parent link="mobile_base"/>
    <child link="ultrasound_rr_sag_base_link"/>
  </joint>
  <link name="ultrasound_rr_sag_base_link"/>
  <!-- Rotate sensor frame (readings are on x axis instead of z) -->
  <joint name="ultrasound_rr_sag_joint" type="fixed">
    <origin rpy="0.0 -1.57 0.0" xyz="0 0 0"/>
    <parent link="ultrasound_rr_sag_base_link"/>
    <child link="ultrasound_rr_sag"/>
  </joint>
  <link name="ultrasound_rr_sag"/>
  <joint name="ultrasound_fl_lat_base_mount_joint" type="fixed">
    <origin rpy="0.0 1.963496 1.570796" xyz="0.4515 0.365 -0.117"/>
    <parent link="mobile_base"/>
    <child link="ultrasound_fl_lat_base_link"/>
  </joint>
  <link name="ultrasound_fl_lat_base_link"/>
  <!-- Rotate sensor frame (readings are on x axis instead of z) -->
  <joint name="ultrasound_fl_lat_joint" type="fixed">
    <origin rpy="0.0 -1.57 0.0" xyz="0 0 0"/>
    <parent link="ultrasound_fl_lat_base_link"/>
    <child link="ultrasound_fl_lat"/>
  </joint>
  <link name="ultrasound_fl_lat"/>
  <joint name="ultrasound_rl_lat_base_mount_joint" type="fixed">
    <origin rpy="0.0 1.963496 1.570796" xyz="-0.4515 0.365 -0.117"/>
    <parent link="mobile_base"/>
    <child link="ultrasound_rl_lat_base_link"/>
  </joint>
  <link name="ultrasound_rl_lat_base_link"/>
  <!-- Rotate sensor frame (readings are on x axis instead of z) -->
  <joint name="ultrasound_rl_lat_joint" type="fixed">
    <origin rpy="0.0 -1.57 0.0" xyz="0 0 0"/>
    <parent link="ultrasound_rl_lat_base_link"/>
    <child link="ultrasound_rl_lat"/>
  </joint>
  <link name="ultrasound_rl_lat"/>
  <joint name="ultrasound_fr_lat_base_mount_joint" type="fixed">
    <origin rpy="0.0 1.963496 -1.570796" xyz="0.4515 -0.365 -0.117"/>
    <parent link="mobile_base"/>
    <child link="ultrasound_fr_lat_base_link"/>
  </joint>
  <link name="ultrasound_fr_lat_base_link"/>
  <!-- Rotate sensor frame (readings are on x axis instead of z) -->
  <joint name="ultrasound_fr_lat_joint" type="fixed">
    <origin rpy="0.0 -1.57 0.0" xyz="0 0 0"/>
    <parent link="ultrasound_fr_lat_base_link"/>
    <child link="ultrasound_fr_lat"/>
  </joint>
  <link name="ultrasound_fr_lat"/>
  <joint name="ultrasound_rr_lat_base_mount_joint" type="fixed">
    <origin rpy="0.0 1.963496 -1.570796" xyz="-0.4515 -0.365 -0.117"/>
    <parent link="mobile_base"/>
    <child link="ultrasound_rr_lat_base_link"/>
  </joint>
  <link name="ultrasound_rr_lat_base_link"/>
  <!-- Rotate sensor frame (readings are on x axis instead of z) -->
  <joint name="ultrasound_rr_lat_joint" type="fixed">
    <origin rpy="0.0 -1.57 0.0" xyz="0 0 0"/>
    <parent link="ultrasound_rr_lat_base_link"/>
    <child link="ultrasound_rr_lat"/>
  </joint>
  <link name="ultrasound_rr_lat"/>
  <gazebo reference="mobile_base">
    <mu1>0.2</mu1>
    <mu2>0.2</mu2>
    <kp>100000000.0</kp>
    <kd>1.0</kd>
    <maxVel>0.0</maxVel>
    <minDepth>0.0001</minDepth>
    <material>Gazebo/Grey</material>
    <selfCollide>True</selfCollide>
  </gazebo>
  <joint name="fixed_J1_A" type="fixed">
    <axis rpy="0 0 0" xyz="0 0 1"/>
    <parent link="mobile_base"/>
    <child link="J1_A_stator"/>
    <origin rpy="-3.141592653589793 -1.5707963267948966 0.0" xyz="0.37925 0.3125 -0.195"/>
  </joint>
  <link name="J1_A_stator">
    <visual>
      <origin rpy="0.0 -0.0 0.0" xyz="0 0 0"/>
      <geometry>
        <mesh filename="package://concert_resources/models/modular/meshes/concert/concert_steering_connection_module.stl" scale="0.001 0.001 0.001"/>
      </geometry>
    </visual>
    <collision>
      <origin rpy="0.0 -0.0 0.0" xyz="0 0 0"/>
      <geometry>
        <mesh filename="package://concert_resources/models/modular/meshes/concert/simple/concert_steering_connection_module.stl" scale="0.001 0.001 0.001"/>
      </geometry>
    </collision>
    <inertial>
      <origin rpy="0 0 0" xyz="-0.0079406061 0.0 0.037039629"/>
      <mass value="1.1813661"/>
      <inertia ixx="0.0026106263" ixy="0.0" ixz="0.00017928188" iyy="0.0027438806" iyz="0.0" izz="0.0025223123"/>
    </inertial>
  </link>
  <gazebo reference="J1_A_stator">
    <mu1>0.2</mu1>
    <mu2>0.2</mu2>
    <kp>100000000.0</kp>
    <kd>1.0</kd>
    <maxVel>0.0</maxVel>
    <minDepth>0.0001</minDepth>
    <material>Gazebo/Blue</material>
    <selfCollide>True</selfCollide>
  </gazebo>
  <joint name="J1_A" type="revolute">
    <axis rpy="0 0 0" xyz="0 0 1"/>
    <parent link="J1_A_stator"/>
    <child link="L_1_A"/>
    <origin rpy="-1.5707963267948966 -0.0 1.5707963267948966" xyz="-0.022 0.0 0.06075"/>
    <limit effort="127.0" lower="-2.6" upper="2.6" velocity="8.1"/>
  </joint>
  <link name="L_1_A">
    <visual>
      <origin rpy="3.141592653589793 -0.0 0.0" xyz="0 0 0"/>
      <geometry>
        <mesh filename="package://concert_resources/models/modular/meshes/concert/concert_steering_module_frame.stl" scale="0.001 0.001 0.001"/>
      </geometry>
    </visual>
    <collision>
      <origin rpy="3.141592653589793 -0.0 0.0" xyz="0 0 0"/>
      <geometry>
        <mesh filename="package://concert_resources/models/modular/meshes/concert/simple/concert_steering_module_frame.stl" scale="0.001 0.001 0.001"/>
      </geometry>
    </collision>
    <inertial>
      <origin rpy="0 0 0" xyz="0.090718433 0.0 0.22670598"/>
      <mass value="7.6995028"/>
      <inertia ixx="0.44048889" ixy="-0.03668535" ixz="0.025595962" iyy="0.52073797" iyz="-0.0026667139" izz="0.69985532"/>
    </inertial>
  </link>
  <gazebo reference="L_1_A">
    <mu1>0.2</mu1>
    <mu2>0.2</mu2>
    <kp>100000000.0</kp>
    <kd>1.0</kd>
    <maxVel>0.0</maxVel>
    <minDepth>0.0001</minDepth>
    <material>Gazebo/White</material>
    <selfCollide>True</selfCollide>
  </gazebo>
  <joint name="fixed_J_wheel_A" type="fixed">
    <axis rpy="0 0 0" xyz="0 0 1"/>
    <parent link="L_1_A"/>
    <child link="J_wheel_A_stator"/>
    <origin rpy="-3.141592653589793 1.5707963267948966 0.0" xyz="0.0 0.0 0.37015"/>
  </joint>
  <link name="J_wheel_A_stator">
    <inertial>
      <mass value="0.001"/>
      <inertia ixx="1.0e-06" ixy="0.0" ixz="0.0" iyy="1.0e-06" iyz="0.0" izz="1.0e-06"/>
    </inertial>
  </link>
  <gazebo reference="J_wheel_A_stator"/>
  <joint name="J_wheel_A" type="revolute">
    <axis rpy="0 0 0" xyz="0 0 1"/>
    <parent link="J_wheel_A_stator"/>
    <child link="wheel_A"/>
    <origin rpy="0.0 -0.0 0.0" xyz="0.0 0.0 0.0"/>
    <limit effort="24.0" lower="-10000000000.0" upper="10000000000.0" velocity="9.5"/>
  </joint>
  <link name="wheel_A">
    <visual>
      <origin rpy="0.0 -0.0 0.0" xyz="0 0 0"/>
      <geometry>
        <mesh filename="package://concert_resources/models/modular/meshes/concert/concert_wheel.stl" scale="0.001 0.001 0.001"/>
      </geometry>
    </visual>
    <collision>
      <origin rpy="0.0 -0.0 0.0" xyz="0 0 0"/>
      <geometry>
        <cylinder length="0.1" radius="0.16"/>
      </geometry>
    </collision>
    <inertial>
      <origin rpy="0 0 0" xyz="0.0 0.0 -0.005"/>
      <mass value="4.0116207"/>
      <inertia ixx="0.028580559" ixy="0.0" ixz="0.0" iyy="0.028580559" iyz="0.0" izz="0.044954065"/>
    </inertial>
  </link>
  <gazebo reference="wheel_A">
    <material>Gazebo/Residential</material>
    <selfCollide>True</selfCollide>
    <collision>
      <surface>
        <friction>
          <ode>
            <mu>1.0</mu>
            <mu2>1.0</mu2>
          </ode>
          <bullet>
            <friction>1.0</friction>
            <friction2>1.0</friction2>
          </bullet>
        </friction>
        <contact>
          <ode>
            <kp>2100000</kp>
            <kd>1</kd>
            <max_vel>100</max_vel>
          </ode>
          <bullet>
            <soft_cfm>0.007</soft_cfm>
            <soft_erp>0.25</soft_erp>
            <kp>1000000</kp>
            <kd>5</kd>
          </bullet>
        </contact>
      </surface>
    </collision>
  </gazebo>
  <joint name="fixed_J1_B" type="fixed">
    <axis rpy="0 0 0" xyz="0 0 1"/>
    <parent link="mobile_base"/>
    <child link="J1_B_stator"/>
    <origin rpy="-3.141592653589793 -1.5707963267948966 0.0" xyz="0.37925 -0.3125 -0.195"/>
  </joint>
  <link name="J1_B_stator">
    <visual>
      <origin rpy="0.0 -0.0 0.0" xyz="0 0 0"/>
      <geometry>
        <mesh filename="package://concert_resources/models/modular/meshes/concert/concert_steering_connection_module.stl" scale="0.001 0.001 0.001"/>
      </geometry>
    </visual>
    <collision>
      <origin rpy="0.0 -0.0 0.0" xyz="0 0 0"/>
      <geometry>
        <mesh filename="package://concert_resources/models/modular/meshes/concert/simple/concert_steering_connection_module.stl" scale="0.001 0.001 0.001"/>
      </geometry>
    </collision>
    <inertial>
      <origin rpy="0 0 0" xyz="-0.0079406061 0.0 0.037039629"/>
      <mass value="1.1813661"/>
      <inertia ixx="0.0026106263" ixy="0.0" ixz="0.00017928188" iyy="0.0027438806" iyz="0.0" izz="0.0025223123"/>
    </inertial>
  </link>
  <gazebo reference="J1_B_stator">
    <mu1>0.2</mu1>
    <mu2>0.2</mu2>
    <kp>100000000.0</kp>
    <kd>1.0</kd>
    <maxVel>0.0</maxVel>
    <minDepth>0.0001</minDepth>
    <material>Gazebo/Blue</material>
    <selfCollide>True</selfCollide>
  </gazebo>
  <joint name="J1_B" type="revolute">
    <axis rpy="0 0 0" xyz="0 0 1"/>
    <parent link="J1_B_stator"/>
    <child link="L_1_B"/>
    <origin rpy="1.5707963267948966 -0.0 -1.5707963267948966" xyz="-0.022 0.0 0.06075"/>
    <limit effort="127.0" lower="-2.6" upper="2.6" velocity="8.1"/>
  </joint>
  <link name="L_1_B">
    <visual>
      <origin rpy="3.141592653589793 -0.0 0.0" xyz="0 0 0"/>
      <geometry>
        <mesh filename="package://concert_resources/models/modular/meshes/concert/concert_steering_module_frame.stl" scale="0.001 0.001 0.001"/>
      </geometry>
    </visual>
    <collision>
      <origin rpy="3.141592653589793 -0.0 0.0" xyz="0 0 0"/>
      <geometry>
        <mesh filename="package://concert_resources/models/modular/meshes/concert/simple/concert_steering_module_frame.stl" scale="0.001 0.001 0.001"/>
      </geometry>
    </collision>
    <inertial>
      <origin rpy="0 0 0" xyz="0.090718433 0.0 0.22670598"/>
      <mass value="7.6995028"/>
      <inertia ixx="0.44048889" ixy="-0.03668535" ixz="0.025595962" iyy="0.52073797" iyz="-0.0026667139" izz="0.69985532"/>
    </inertial>
  </link>
  <gazebo reference="L_1_B">
    <mu1>0.2</mu1>
    <mu2>0.2</mu2>
    <kp>100000000.0</kp>
    <kd>1.0</kd>
    <maxVel>0.0</maxVel>
    <minDepth>0.0001</minDepth>
    <material>Gazebo/White</material>
    <selfCollide>True</selfCollide>
  </gazebo>
  <joint name="fixed_J_wheel_B" type="fixed">
    <axis rpy="0 0 0" xyz="0 0 1"/>
    <parent link="L_1_B"/>
    <child link="J_wheel_B_stator"/>
    <origin rpy="-3.141592653589793 1.5707963267948966 0.0" xyz="0.0 0.0 0.37015"/>
  </joint>
  <link name="J_wheel_B_stator">
    <inertial>
      <mass value="0.001"/>
      <inertia ixx="1.0e-06" ixy="0.0" ixz="0.0" iyy="1.0e-06" iyz="0.0" izz="1.0e-06"/>
    </inertial>
  </link>
  <gazebo reference="J_wheel_B_stator"/>
  <joint name="J_wheel_B" type="revolute">
    <axis rpy="0 0 0" xyz="0 0 1"/>
    <parent link="J_wheel_B_stator"/>
    <child link="wheel_B"/>
    <origin rpy="0.0 -0.0 0.0" xyz="0.0 0.0 0.0"/>
    <limit effort="24.0" lower="-10000000000.0" upper="10000000000.0" velocity="9.5"/>
  </joint>
  <link name="wheel_B">
    <visual>
      <origin rpy="0.0 -0.0 0.0" xyz="0 0 0"/>
      <geometry>
        <mesh filename="package://concert_resources/models/modular/meshes/concert/concert_wheel.stl" scale="0.001 0.001 0.001"/>
      </geometry>
    </visual>
    <collision>
      <origin rpy="0.0 -0.0 0.0" xyz="0 0 0"/>
      <geometry>
        <cylinder length="0.1" radius="0.16"/>
      </geometry>
    </collision>
    <inertial>
      <origin rpy="0 0 0" xyz="0.0 0.0 -0.005"/>
      <mass value="4.0116207"/>
      <inertia ixx="0.028580559" ixy="0.0" ixz="0.0" iyy="0.028580559" iyz="0.0" izz="0.044954065"/>
    </inertial>
  </link>
  <gazebo reference="wheel_B">
    <material>Gazebo/Residential</material>
    <selfCollide>True</selfCollide>
    <collision>
      <surface>
        <friction>
          <ode>
            <mu>1.0</mu>
            <mu2>1.0</mu2>
          </ode>
          <bullet>
            <friction>1.0</friction>
            <friction2>1.0</friction2>
          </bullet>
        </friction>
        <contact>
          <ode>
            <kp>2100000</kp>
            <kd>1</kd>
            <max_vel>100</max_vel>
          </ode>
          <bullet>
            <soft_cfm>0.007</soft_cfm>
            <soft_erp>0.25</soft_erp>
            <kp>1000000</kp>
            <kd>5</kd>
          </bullet>
        </contact>
      </surface>
    </collision>
  </gazebo>
  <joint name="fixed_J1_C" type="fixed">
    <axis rpy="0 0 0" xyz="0 0 1"/>
    <parent link="mobile_base"/>
    <child link="J1_C_stator"/>
    <origin rpy="-0.0 -1.5707963267948966 0.0" xyz="-0.37925 0.3125 -0.195"/>
  </joint>
  <link name="J1_C_stator">
    <visual>
      <origin rpy="0.0 -0.0 0.0" xyz="0 0 0"/>
      <geometry>
        <mesh filename="package://concert_resources/models/modular/meshes/concert/concert_steering_connection_module.stl" scale="0.001 0.001 0.001"/>
      </geometry>
    </visual>
    <collision>
      <origin rpy="0.0 -0.0 0.0" xyz="0 0 0"/>
      <geometry>
        <mesh filename="package://concert_resources/models/modular/meshes/concert/simple/concert_steering_connection_module.stl" scale="0.001 0.001 0.001"/>
      </geometry>
    </collision>
    <inertial>
      <origin rpy="0 0 0" xyz="-0.0079406061 0.0 0.037039629"/>
      <mass value="1.1813661"/>
      <inertia ixx="0.0026106263" ixy="0.0" ixz="0.00017928188" iyy="0.0027438806" iyz="0.0" izz="0.0025223123"/>
    </inertial>
  </link>
  <gazebo reference="J1_C_stator">
    <mu1>0.2</mu1>
    <mu2>0.2</mu2>
    <kp>100000000.0</kp>
    <kd>1.0</kd>
    <maxVel>0.0</maxVel>
    <minDepth>0.0001</minDepth>
    <material>Gazebo/Blue</material>
    <selfCollide>True</selfCollide>
  </gazebo>
  <joint name="J1_C" type="revolute">
    <axis rpy="0 0 0" xyz="0 0 1"/>
    <parent link="J1_C_stator"/>
    <child link="L_1_C"/>
    <origin rpy="1.5707963267948966 -0.0 -1.5707963267948966" xyz="-0.022 0.0 0.06075"/>
    <limit effort="127.0" lower="-2.6" upper="2.6" velocity="8.1"/>
  </joint>
  <link name="L_1_C">
    <visual>
      <origin rpy="3.141592653589793 -0.0 0.0" xyz="0 0 0"/>
      <geometry>
        <mesh filename="package://concert_resources/models/modular/meshes/concert/concert_steering_module_frame.stl" scale="0.001 0.001 0.001"/>
      </geometry>
    </visual>
    <collision>
      <origin rpy="3.141592653589793 -0.0 0.0" xyz="0 0 0"/>
      <geometry>
        <mesh filename="package://concert_resources/models/modular/meshes/concert/simple/concert_steering_module_frame.stl" scale="0.001 0.001 0.001"/>
      </geometry>
    </collision>
    <inertial>
      <origin rpy="0 0 0" xyz="0.090718433 0.0 0.22670598"/>
      <mass value="7.6995028"/>
      <inertia ixx="0.44048889" ixy="-0.03668535" ixz="0.025595962" iyy="0.52073797" iyz="-0.0026667139" izz="0.69985532"/>
    </inertial>
  </link>
  <gazebo reference="L_1_C">
    <mu1>0.2</mu1>
    <mu2>0.2</mu2>
    <kp>100000000.0</kp>
    <kd>1.0</kd>
    <maxVel>0.0</maxVel>
    <minDepth>0.0001</minDepth>
    <material>Gazebo/White</material>
    <selfCollide>True</selfCollide>
  </gazebo>
  <joint name="fixed_J_wheel_C" type="fixed">
    <axis rpy="0 0 0" xyz="0 0 1"/>
    <parent link="L_1_C"/>
    <child link="J_wheel_C_stator"/>
    <origin rpy="-3.141592653589793 1.5707963267948966 0.0" xyz="0.0 0.0 0.37015"/>
  </joint>
  <link name="J_wheel_C_stator">
    <inertial>
      <mass value="0.001"/>
      <inertia ixx="1.0e-06" ixy="0.0" ixz="0.0" iyy="1.0e-06" iyz="0.0" izz="1.0e-06"/>
    </inertial>
  </link>
  <gazebo reference="J_wheel_C_stator"/>
  <joint name="J_wheel_C" type="revolute">
    <axis rpy="0 0 0" xyz="0 0 1"/>
    <parent link="J_wheel_C_stator"/>
    <child link="wheel_C"/>
    <origin rpy="0.0 -0.0 0.0" xyz="0.0 0.0 0.0"/>
    <limit effort="24.0" lower="-10000000000.0" upper="10000000000.0" velocity="9.5"/>
  </joint>
  <link name="wheel_C">
    <visual>
      <origin rpy="0.0 -0.0 0.0" xyz="0 0 0"/>
      <geometry>
        <mesh filename="package://concert_resources/models/modular/meshes/concert/concert_wheel.stl" scale="0.001 0.001 0.001"/>
      </geometry>
    </visual>
    <collision>
      <origin rpy="0.0 -0.0 0.0" xyz="0 0 0"/>
      <geometry>
        <cylinder length="0.1" radius="0.16"/>
      </geometry>
    </collision>
    <inertial>
      <origin rpy="0 0 0" xyz="0.0 0.0 -0.005"/>
      <mass value="4.0116207"/>
      <inertia ixx="0.028580559" ixy="0.0" ixz="0.0" iyy="0.028580559" iyz="0.0" izz="0.044954065"/>
    </inertial>
  </link>
  <gazebo reference="wheel_C">
    <material>Gazebo/Residential</material>
    <selfCollide>True</selfCollide>
    <collision>
      <surface>
        <friction>
          <ode>
            <mu>1.0</mu>
            <mu2>1.0</mu2>
          </ode>
          <bullet>
            <friction>1.0</friction>
            <friction2>1.0</friction2>
          </bullet>
        </friction>
        <contact>
          <ode>
            <kp>2100000</kp>
            <kd>1</kd>
            <max_vel>100</max_vel>
          </ode>
          <bullet>
            <soft_cfm>0.007</soft_cfm>
            <soft_erp>0.25</soft_erp>
            <kp>1000000</kp>
            <kd>5</kd>
          </bullet>
        </contact>
      </surface>
    </collision>
  </gazebo>
  <joint name="fixed_J1_D" type="fixed">
    <axis rpy="0 0 0" xyz="0 0 1"/>
    <parent link="mobile_base"/>
    <child link="J1_D_stator"/>
    <origin rpy="-0.0 -1.5707963267948966 0.0" xyz="-0.37925 -0.3125 -0.195"/>
  </joint>
  <link name="J1_D_stator">
    <visual>
      <origin rpy="0.0 -0.0 0.0" xyz="0 0 0"/>
      <geometry>
        <mesh filename="package://concert_resources/models/modular/meshes/concert/concert_steering_connection_module.stl" scale="0.001 0.001 0.001"/>
      </geometry>
    </visual>
    <collision>
      <origin rpy="0.0 -0.0 0.0" xyz="0 0 0"/>
      <geometry>
        <mesh filename="package://concert_resources/models/modular/meshes/concert/simple/concert_steering_connection_module.stl" scale="0.001 0.001 0.001"/>
      </geometry>
    </collision>
    <inertial>
      <origin rpy="0 0 0" xyz="-0.0079406061 0.0 0.037039629"/>
      <mass value="1.1813661"/>
      <inertia ixx="0.0026106263" ixy="0.0" ixz="0.00017928188" iyy="0.0027438806" iyz="0.0" izz="0.0025223123"/>
    </inertial>
  </link>
  <gazebo reference="J1_D_stator">
    <mu1>0.2</mu1>
    <mu2>0.2</mu2>
    <kp>100000000.0</kp>
    <kd>1.0</kd>
    <maxVel>0.0</maxVel>
    <minDepth>0.0001</minDepth>
    <material>Gazebo/Blue</material>
    <selfCollide>True</selfCollide>
  </gazebo>
  <joint name="J1_D" type="revolute">
    <axis rpy="0 0 0" xyz="0 0 1"/>
    <parent link="J1_D_stator"/>
    <child link="L_1_D"/>
    <origin rpy="-1.5707963267948966 -0.0 1.5707963267948966" xyz="-0.022 0.0 0.06075"/>
    <limit effort="127.0" lower="-2.6" upper="2.6" velocity="8.1"/>
  </joint>
  <link name="L_1_D">
    <visual>
      <origin rpy="3.141592653589793 -0.0 0.0" xyz="0 0 0"/>
      <geometry>
        <mesh filename="package://concert_resources/models/modular/meshes/concert/concert_steering_module_frame.stl" scale="0.001 0.001 0.001"/>
      </geometry>
    </visual>
    <collision>
      <origin rpy="3.141592653589793 -0.0 0.0" xyz="0 0 0"/>
      <geometry>
        <mesh filename="package://concert_resources/models/modular/meshes/concert/simple/concert_steering_module_frame.stl" scale="0.001 0.001 0.001"/>
      </geometry>
    </collision>
    <inertial>
      <origin rpy="0 0 0" xyz="0.090718433 0.0 0.22670598"/>
      <mass value="7.6995028"/>
      <inertia ixx="0.44048889" ixy="-0.03668535" ixz="0.025595962" iyy="0.52073797" iyz="-0.0026667139" izz="0.69985532"/>
    </inertial>
  </link>
  <gazebo reference="L_1_D">
    <mu1>0.2</mu1>
    <mu2>0.2</mu2>
    <kp>100000000.0</kp>
    <kd>1.0</kd>
    <maxVel>0.0</maxVel>
    <minDepth>0.0001</minDepth>
    <material>Gazebo/White</material>
    <selfCollide>True</selfCollide>
  </gazebo>
  <joint name="fixed_J_wheel_D" type="fixed">
    <axis rpy="0 0 0" xyz="0 0 1"/>
    <parent link="L_1_D"/>
    <child link="J_wheel_D_stator"/>
    <origin rpy="-3.141592653589793 1.5707963267948966 0.0" xyz="0.0 0.0 0.37015"/>
  </joint>
  <link name="J_wheel_D_stator">
    <inertial>
      <mass value="0.001"/>
      <inertia ixx="1.0e-06" ixy="0.0" ixz="0.0" iyy="1.0e-06" iyz="0.0" izz="1.0e-06"/>
    </inertial>
  </link>
  <gazebo reference="J_wheel_D_stator"/>
  <joint name="J_wheel_D" type="revolute">
    <axis rpy="0 0 0" xyz="0 0 1"/>
    <parent link="J_wheel_D_stator"/>
    <child link="wheel_D"/>
    <origin rpy="0.0 -0.0 0.0" xyz="0.0 0.0 0.0"/>
    <limit effort="24.0" lower="-10000000000.0" upper="10000000000.0" velocity="9.5"/>
  </joint>
  <link name="wheel_D">
    <visual>
      <origin rpy="0.0 -0.0 0.0" xyz="0 0 0"/>
      <geometry>
        <mesh filename="package://concert_resources/models/modular/meshes/concert/concert_wheel.stl" scale="0.001 0.001 0.001"/>
      </geometry>
    </visual>
    <collision>
      <origin rpy="0.0 -0.0 0.0" xyz="0 0 0"/>
      <geometry>
        <cylinder length="0.1" radius="0.16"/>
      </geometry>
    </collision>
    <inertial>
      <origin rpy="0 0 0" xyz="0.0 0.0 -0.005"/>
      <mass value="4.0116207"/>
      <inertia ixx="0.028580559" ixy="0.0" ixz="0.0" iyy="0.028580559" iyz="0.0" izz="0.044954065"/>
    </inertial>
  </link>
  <gazebo reference="wheel_D">
    <material>Gazebo/Residential</material>
    <selfCollide>True</selfCollide>
    <collision>
      <surface>
        <friction>
          <ode>
            <mu>1.0</mu>
            <mu2>1.0</mu2>
          </ode>
          <bullet>
            <friction>1.0</friction>
            <friction2>1.0</friction2>
          </bullet>
        </friction>
        <contact>
          <ode>
            <kp>2100000</kp>
            <kd>1</kd>
            <max_vel>100</max_vel>
          </ode>
          <bullet>
            <soft_cfm>0.007</soft_cfm>
            <soft_erp>0.25</soft_erp>
            <kp>1000000</kp>
            <kd>5</kd>
          </bullet>
        </contact>
      </surface>
    </collision>
  </gazebo>
  <joint name="fixed_J1_E" type="fixed">
    <axis rpy="0 0 0" xyz="0 0 1"/>
    <parent link="mobile_base"/>
    <child link="J1_E_stator"/>
    <origin rpy="0.0 -0.0 3.141592653589793" xyz="0.2 0.0 0.016"/>
  </joint>
  <link name="J1_E_stator">
    <visual>
      <origin rpy="0.0 -0.0 0.0" xyz="0 0 0"/>
      <geometry>
        <mesh filename="package://concert_resources/models/modular/meshes/concert/concert_yaw-base.stl" scale="0.001 0.001 0.001"/>
      </geometry>
    </visual>
    <collision>
      <origin rpy="0.0 -0.0 0.0" xyz="0 0 0"/>
      <geometry>
        <mesh filename="package://concert_resources/models/modular/meshes/concert/simple/concert_yaw-base.stl" scale="0.001 0.001 0.001"/>
      </geometry>
    </collision>
    <inertial>
      <origin rpy="0 0 0" xyz="0.0 0.0 0.121"/>
      <mass value="3.586681"/>
      <inertia ixx="0.017808349" ixy="1.6625281e-06" ixz="-1.8023262e-05" iyy="0.017503159" iyz="-6.8557387e-05" izz="0.0068844202"/>
    </inertial>
  </link>
  <gazebo reference="J1_E_stator">
    <mu1>0.2</mu1>
    <mu2>0.2</mu2>
    <kp>100000000.0</kp>
    <kd>1.0</kd>
    <maxVel>0.0</maxVel>
    <minDepth>0.0001</minDepth>
    <material>Gazebo/Blue</material>
    <selfCollide>True</selfCollide>
  </gazebo>
  <joint name="J1_E" type="revolute">
    <axis rpy="0 0 0" xyz="0 0 1"/>
    <parent link="J1_E_stator"/>
    <child link="L_1_E"/>
    <origin rpy="0.0 -0.0 0.0" xyz="0.0 0.0 0.22316"/>
    <limit effort="460.0" lower="-3.0" upper="3.0" velocity="2.14"/>
  </joint>
  <link name="L_1_E">
    <visual>
      <origin rpy="0.0 -0.0 0.0" xyz="0 0 0"/>
      <geometry>
        <mesh filename="package://concert_resources/models/modular/meshes/concert/concert_yaw-link.stl" scale="0.001 0.001 0.001"/>
      </geometry>
    </visual>
    <collision>
      <origin rpy="0.0 -0.0 0.0" xyz="0 0 0"/>
      <geometry>
        <mesh filename="package://concert_resources/models/modular/meshes/concert/simple/concert_yaw-link.stl" scale="0.001 0.001 0.001"/>
      </geometry>
    </collision>
    <inertial>
      <origin rpy="0 0 0" xyz="0.0 0.0 0.001875"/>
      <mass value="0.57797267"/>
      <inertia ixx="0.00098277371" ixy="9.0821713e-08" ixz="-7.1612945e-08" iyy="0.0009834362" iyz="0.0" izz="0.0016259552"/>
    </inertial>
  </link>
  <gazebo reference="L_1_E">
    <mu1>0.2</mu1>
    <mu2>0.2</mu2>
    <kp>100000000.0</kp>
    <kd>1.0</kd>
    <maxVel>0.0</maxVel>
    <minDepth>0.0001</minDepth>
    <material>Gazebo/White</material>
    <selfCollide>True</selfCollide>
  </gazebo>
  <joint name="fixed_J2_E" type="fixed">
    <axis rpy="0 0 0" xyz="0 0 1"/>
    <parent link="L_1_E"/>
    <child link="J2_E_stator"/>
    <origin rpy="0.0 -0.0 0.0" xyz="0.0 0.0 0.02184"/>
  </joint>
  <link name="J2_E_stator">
    <visual>
      <origin rpy="0.0 -0.0 0.0" xyz="0 0 0"/>
      <geometry>
        <mesh filename="package://concert_resources/models/modular/meshes/concert/concert_elbow-base.stl" scale="0.001 0.001 0.001"/>
      </geometry>
    </visual>
    <collision>
      <origin rpy="0.0 -0.0 0.0" xyz="0 0 0"/>
      <geometry>
        <mesh filename="package://concert_resources/models/modular/meshes/concert/simple/concert_elbow-base.stl" scale="0.001 0.001 0.001"/>
      </geometry>
    </collision>
    <inertial>
      <origin rpy="0 0 0" xyz="-0.001149215 0.042825109 0.076804506"/>
      <mass value="3.6144181"/>
      <inertia ixx="0.015371313" ixy="-9.9563906e-05" ixz="9.0045644e-06" iyy="0.0086766316" iyz="-0.0018673171" izz="0.013320926"/>
    </inertial>
  </link>
  <gazebo reference="J2_E_stator">
    <mu1>0.2</mu1>
    <mu2>0.2</mu2>
    <kp>100000000.0</kp>
    <kd>1.0</kd>
    <maxVel>0.0</maxVel>
    <minDepth>0.0001</minDepth>
    <material>Gazebo/Blue</material>
    <selfCollide>True</selfCollide>
  </gazebo>
  <joint name="J2_E" type="revolute">
    <axis rpy="0 0 0" xyz="0 0 1"/>
    <parent link="J2_E_stator"/>
    <child link="L_2_E"/>
    <origin rpy="-1.5707963267948966 -0.0 0.0" xyz="0.0 0.13666 0.0875"/>
    <limit effort="460.0" lower="-3.0" upper="3.0" velocity="2.14"/>
  </joint>
  <link name="L_2_E">
    <visual>
      <origin rpy="0.0 -0.0 0.0" xyz="0 0 0"/>
      <geometry>
        <mesh filename="package://concert_resources/models/modular/meshes/concert/concert_elbow-link.stl" scale="0.001 0.001 0.001"/>
      </geometry>
    </visual>
    <collision>
      <origin rpy="0.0 -0.0 0.0" xyz="0 0 0"/>
      <geometry>
        <mesh filename="package://concert_resources/models/modular/meshes/concert/simple/concert_elbow-link.stl" scale="0.001 0.001 0.001"/>
      </geometry>
    </collision>
    <inertial>
      <origin rpy="0 0 0" xyz="0.0 -0.028238874 0.017527776"/>
      <mass value="1.1481338"/>
      <inertia ixx="0.0034928397" ixy="-1.0903971e-05" ixz="6.2736548e-06" iyy="0.0029687575" iyz="0.00031199793" izz="0.0042223026"/>
    </inertial>
  </link>
  <gazebo reference="L_2_E">
    <mu1>0.2</mu1>
    <mu2>0.2</mu2>
    <kp>100000000.0</kp>
    <kd>1.0</kd>
    <maxVel>0.0</maxVel>
    <minDepth>0.0001</minDepth>
    <material>Gazebo/White</material>
    <selfCollide>True</selfCollide>
  </gazebo>
  <joint name="fixed_J3_E" type="fixed">
    <axis rpy="0 0 0" xyz="0 0 1"/>
    <parent link="L_2_E"/>
    <child link="J3_E_stator"/>
    <origin rpy="-1.5707963267948966 -0.0 3.141592653589793" xyz="0.0 -0.0875 0.0195"/>
  </joint>
  <link name="J3_E_stator">
    <visual>
      <origin rpy="0.0 -0.0 0.0" xyz="0 0 0"/>
      <geometry>
        <mesh filename="package://concert_resources/models/modular/meshes/concert/concert_yaw-base.stl" scale="0.001 0.001 0.001"/>
      </geometry>
    </visual>
    <collision>
      <origin rpy="0.0 -0.0 0.0" xyz="0 0 0"/>
      <geometry>
        <mesh filename="package://concert_resources/models/modular/meshes/concert/simple/concert_yaw-base.stl" scale="0.001 0.001 0.001"/>
      </geometry>
    </collision>
    <inertial>
      <origin rpy="0 0 0" xyz="0.0 0.0 0.11767718"/>
      <mass value="3.2592751"/>
      <inertia ixx="0.017046707" ixy="-2.9108359e-07" ixz="-6.3074987e-06" iyy="0.016747265" iyz="-5.7883896e-05" izz="0.0060549298"/>
    </inertial>
  </link>
  <gazebo reference="J3_E_stator">
    <mu1>0.2</mu1>
    <mu2>0.2</mu2>
    <kp>100000000.0</kp>
    <kd>1.0</kd>
    <maxVel>0.0</maxVel>
    <minDepth>0.0001</minDepth>
    <material>Gazebo/Blue</material>
    <selfCollide>True</selfCollide>
  </gazebo>
  <joint name="J3_E" type="revolute">
    <axis rpy="0 0 0" xyz="0 0 1"/>
    <parent link="J3_E_stator"/>
    <child link="L_3_E"/>
    <origin rpy="0.0 -0.0 0.0" xyz="0.0 0.0 0.22316"/>
    <limit effort="314.0" lower="-3.0" upper="3.0" velocity="2.85"/>
  </joint>
  <link name="L_3_E">
    <visual>
      <origin rpy="0.0 -0.0 0.0" xyz="0 0 0"/>
      <geometry>
        <mesh filename="package://concert_resources/models/modular/meshes/concert/concert_yaw-link.stl" scale="0.001 0.001 0.001"/>
      </geometry>
    </visual>
    <collision>
      <origin rpy="0.0 -0.0 0.0" xyz="0 0 0"/>
      <geometry>
        <mesh filename="package://concert_resources/models/modular/meshes/concert/simple/concert_yaw-link.stl" scale="0.001 0.001 0.001"/>
      </geometry>
    </collision>
    <inertial>
      <origin rpy="0 0 0" xyz="0.0 0.0 -0.02"/>
      <mass value="0.56725368"/>
      <inertia ixx="0.00097738346" ixy="9.078518e-08" ixz="5.0589486e-08" iyy="0.00097804563" iyz="0.0" izz="0.001617678"/>
    </inertial>
  </link>
  <gazebo reference="L_3_E">
    <mu1>0.2</mu1>
    <mu2>0.2</mu2>
    <kp>100000000.0</kp>
    <kd>1.0</kd>
    <maxVel>0.0</maxVel>
    <minDepth>0.0001</minDepth>
    <material>Gazebo/White</material>
    <selfCollide>True</selfCollide>
  </gazebo>
  <joint name="fixed_J4_E" type="fixed">
    <axis rpy="0 0 0" xyz="0 0 1"/>
    <parent link="L_3_E"/>
    <child link="J4_E_stator"/>
    <origin rpy="0.0 -0.0 0.0" xyz="0.0 0.0 0.02184"/>
  </joint>
  <link name="J4_E_stator">
    <visual>
      <origin rpy="0.0 -0.0 0.0" xyz="0 0 0"/>
      <geometry>
        <mesh filename="package://concert_resources/models/modular/meshes/concert/concert_elbow-base.stl" scale="0.001 0.001 0.001"/>
      </geometry>
    </visual>
    <collision>
      <origin rpy="0.0 -0.0 0.0" xyz="0 0 0"/>
      <geometry>
        <mesh filename="package://concert_resources/models/modular/meshes/concert/simple/concert_elbow-base.stl" scale="0.001 0.001 0.001"/>
      </geometry>
    </collision>
    <inertial>
      <origin rpy="0 0 0" xyz="-0.001149215 0.042825109 0.076804506"/>
      <mass value="3.6144181"/>
      <inertia ixx="0.015371313" ixy="-9.9563906e-05" ixz="9.0045644e-06" iyy="0.0086766316" iyz="-0.0018673171" izz="0.013320926"/>
    </inertial>
  </link>
  <gazebo reference="J4_E_stator">
    <mu1>0.2</mu1>
    <mu2>0.2</mu2>
    <kp>100000000.0</kp>
    <kd>1.0</kd>
    <maxVel>0.0</maxVel>
    <minDepth>0.0001</minDepth>
    <material>Gazebo/Blue</material>
    <selfCollide>True</selfCollide>
  </gazebo>
  <joint name="J4_E" type="revolute">
    <axis rpy="0 0 0" xyz="0 0 1"/>
    <parent link="J4_E_stator"/>
    <child link="L_4_E"/>
    <origin rpy="-1.5707963267948966 -0.0 0.0" xyz="0.0 0.13666 0.0875"/>
    <limit effort="460.0" lower="-3.0" upper="3.0" velocity="2.14"/>
  </joint>
  <link name="L_4_E">
    <visual>
      <origin rpy="0.0 -0.0 0.0" xyz="0 0 0"/>
      <geometry>
        <mesh filename="package://concert_resources/models/modular/meshes/concert/concert_elbow-link.stl" scale="0.001 0.001 0.001"/>
      </geometry>
    </visual>
    <collision>
      <origin rpy="0.0 -0.0 0.0" xyz="0 0 0"/>
      <geometry>
        <mesh filename="package://concert_resources/models/modular/meshes/concert/simple/concert_elbow-link.stl" scale="0.001 0.001 0.001"/>
      </geometry>
    </collision>
    <inertial>
      <origin rpy="0 0 0" xyz="0.0 -0.028238874 0.017527776"/>
      <mass value="1.1481338"/>
      <inertia ixx="0.0034928397" ixy="-1.0903971e-05" ixz="6.2736548e-06" iyy="0.0029687575" iyz="0.00031199793" izz="0.0042223026"/>
    </inertial>
  </link>
  <gazebo reference="L_4_E">
    <mu1>0.2</mu1>
    <mu2>0.2</mu2>
    <kp>100000000.0</kp>
    <kd>1.0</kd>
    <maxVel>0.0</maxVel>
    <minDepth>0.0001</minDepth>
    <material>Gazebo/White</material>
    <selfCollide>True</selfCollide>
  </gazebo>
  <joint name="fixed_J5_E" type="fixed">
    <axis rpy="0 0 0" xyz="0 0 1"/>
    <parent link="L_4_E"/>
    <child link="J5_E_stator"/>
    <origin rpy="-1.5707963267948966 -0.0 3.141592653589793" xyz="0.0 -0.0875 0.0195"/>
  </joint>
  <link name="J5_E_stator">
    <visual>
      <origin rpy="0.0 -0.0 0.0" xyz="0 0 0"/>
      <geometry>
        <mesh filename="package://concert_resources/models/modular/meshes/concert/concert_yaw-base.stl" scale="0.001 0.001 0.001"/>
      </geometry>
    </visual>
    <collision>
      <origin rpy="0.0 -0.0 0.0" xyz="0 0 0"/>
      <geometry>
        <mesh filename="package://concert_resources/models/modular/meshes/concert/simple/concert_yaw-base.stl" scale="0.001 0.001 0.001"/>
      </geometry>
    </collision>
    <inertial>
      <origin rpy="0 0 0" xyz="0.0 0.0 0.11767718"/>
      <mass value="3.2592751"/>
      <inertia ixx="0.017046707" ixy="-2.9108359e-07" ixz="-6.3074987e-06" iyy="0.016747265" iyz="-5.7883896e-05" izz="0.0060549298"/>
    </inertial>
  </link>
  <gazebo reference="J5_E_stator">
    <mu1>0.2</mu1>
    <mu2>0.2</mu2>
    <kp>100000000.0</kp>
    <kd>1.0</kd>
    <maxVel>0.0</maxVel>
    <minDepth>0.0001</minDepth>
    <material>Gazebo/Blue</material>
    <selfCollide>True</selfCollide>
  </gazebo>
  <joint name="J5_E" type="revolute">
    <axis rpy="0 0 0" xyz="0 0 1"/>
    <parent link="J5_E_stator"/>
    <child link="L_5_E"/>
    <origin rpy="0.0 -0.0 0.0" xyz="0.0 0.0 0.22316"/>
    <limit effort="314.0" lower="-3.0" upper="3.0" velocity="2.85"/>
  </joint>
  <link name="L_5_E">
    <visual>
      <origin rpy="0.0 -0.0 0.0" xyz="0 0 0"/>
      <geometry>
        <mesh filename="package://concert_resources/models/modular/meshes/concert/concert_yaw-link.stl" scale="0.001 0.001 0.001"/>
      </geometry>
    </visual>
    <collision>
      <origin rpy="0.0 -0.0 0.0" xyz="0 0 0"/>
      <geometry>
        <mesh filename="package://concert_resources/models/modular/meshes/concert/simple/concert_yaw-link.stl" scale="0.001 0.001 0.001"/>
      </geometry>
    </collision>
    <inertial>
      <origin rpy="0 0 0" xyz="0.0 0.0 -0.02"/>
      <mass value="0.56725368"/>
      <inertia ixx="0.00097738346" ixy="9.078518e-08" ixz="5.0589486e-08" iyy="0.00097804563" iyz="0.0" izz="0.001617678"/>
    </inertial>
  </link>
  <gazebo reference="L_5_E">
    <mu1>0.2</mu1>
    <mu2>0.2</mu2>
    <kp>100000000.0</kp>
    <kd>1.0</kd>
    <maxVel>0.0</maxVel>
    <minDepth>0.0001</minDepth>
    <material>Gazebo/White</material>
    <selfCollide>True</selfCollide>
  </gazebo>
  <joint name="fixed_J6_E" type="fixed">
    <axis rpy="0 0 0" xyz="0 0 1"/>
    <parent link="L_5_E"/>
    <child link="J6_E_stator"/>
    <origin rpy="0.0 -0.0 0.0" xyz="0.0 0.0 0.02184"/>
  </joint>
  <link name="J6_E_stator">
    <visual>
      <origin rpy="0.0 -0.0 0.0" xyz="0 0 0"/>
      <geometry>
        <mesh filename="package://concert_resources/models/modular/meshes/concert/concert_elbow-base.stl" scale="0.001 0.001 0.001"/>
      </geometry>
    </visual>
    <collision>
      <origin rpy="0.0 -0.0 0.0" xyz="0 0 0"/>
      <geometry>
        <mesh filename="package://concert_resources/models/modular/meshes/concert/simple/concert_elbow-base.stl" scale="0.001 0.001 0.001"/>
      </geometry>
    </collision>
    <inertial>
      <origin rpy="0 0 0" xyz="-0.0011761517 0.041312534 0.075772157"/>
      <mass value="3.3057881"/>
      <inertia ixx="0.014381278" ixy="-8.2901107e-05" ixz="2.7564183e-05" iyy="0.0078716547" iyz="-0.0018208015" izz="0.012353539"/>
    </inertial>
  </link>
  <gazebo reference="J6_E_stator">
    <mu1>0.2</mu1>
    <mu2>0.2</mu2>
    <kp>100000000.0</kp>
    <kd>1.0</kd>
    <maxVel>0.0</maxVel>
    <minDepth>0.0001</minDepth>
    <material>Gazebo/Blue</material>
    <selfCollide>True</selfCollide>
  </gazebo>
  <joint name="J6_E" type="revolute">
    <axis rpy="0 0 0" xyz="0 0 1"/>
    <parent link="J6_E_stator"/>
    <child link="L_6_E"/>
    <origin rpy="-1.5707963267948966 -0.0 0.0" xyz="0.0 0.13666 0.0875"/>
    <limit effort="314.0" lower="-3.0" upper="3.0" velocity="2.85"/>
  </joint>
  <link name="L_6_E">
    <visual>
      <origin rpy="0.0 -0.0 0.0" xyz="0 0 0"/>
      <geometry>
        <mesh filename="package://concert_resources/models/modular/meshes/concert/concert_elbow-link.stl" scale="0.001 0.001 0.001"/>
      </geometry>
    </visual>
    <collision>
      <origin rpy="0.0 -0.0 0.0" xyz="0 0 0"/>
      <geometry>
        <mesh filename="package://concert_resources/models/modular/meshes/concert/simple/concert_elbow-link.stl" scale="0.001 0.001 0.001"/>
      </geometry>
    </collision>
    <inertial>
      <origin rpy="0 0 0" xyz="0.0 -0.028683616 0.017545874"/>
      <mass value="1.1588784"/>
      <inertia ixx="0.0034928397" ixy="-1.0903971e-05" ixz="6.2736548e-06" iyy="0.0029687575" iyz="0.00031199793" izz="0.0042223026"/>
    </inertial>
  </link>
  <gazebo reference="L_6_E">
    <mu1>0.2</mu1>
    <mu2>0.2</mu2>
    <kp>100000000.0</kp>
    <kd>1.0</kd>
    <maxVel>0.0</maxVel>
    <minDepth>0.0001</minDepth>
    <material>Gazebo/White</material>
    <selfCollide>True</selfCollide>
  </gazebo>
  <link name="ee_E">
    <visual>
      <origin rpy="0 0 0" xyz="0 0 -0.1"/>
      <geometry>
        <cylinder length="0.2" radius="0.02"/>
      </geometry>
      <material name="blue"/>
    </visual>
    <collision>
      <origin rpy="0 0 0" xyz="0 0 -0.1"/>
      <geometry>
        <cylinder length="0.2" radius="0.02"/>
      </geometry>
    </collision>
    <inertial>
      <origin rpy="0 0 0" xyz="0 0 0.1"/>
      <mass value="1.0"/>
      <inertia ixx="0.003433333333333334" ixy="0.0" ixz="0.0" iyy="0.003433333333333334" iyz="0.0" izz="0.0002"/>
    </inertial>
  </link>
  <joint name="L_6_fixed_joint_1_E" type="fixed">
    <axis rpy="0 0 0" xyz="0 0 1"/>
    <parent link="L_6_E"/>
    <child link="ee_E"/>
    <origin rpy="-1.5707963267948966 -0.0 3.141592653589793" xyz="0.0 -0.2875 0.0195"/>
  </joint>
</robot>

