<?xml version="1.0" encoding="utf-8"?>
<robot name="ModularBot">
  <material name="blue">
    <color rgba="0 0 0.8 1"/>
  </material>
  <material name="black">
    <color rgba="0 0 0 1"/>
  </material>
  <material name="white">
    <color rgba="1 1 1 1"/>
  </material>
  <material name="grey">
    <color rgba="0.5 0.5 0.5 1"/>
  </material>
  <material name="red">
    <color rgba="1 0 0 1"/>
  </material>
  <material name="green">
    <color rgba="0 1 0 1"/>
  </material>
  <material name="yellow">
    <color rgba="1 1 0 1"/>
  </material>
  <material name="tree_green">
    <color rgba="0.13 0.54 0.13 1"/>
  </material>
  <link name="world"/>
  <joint name="reference" type="fixed">
    <parent link="world"/>
    <child link="base_link"/>
  </joint>
  <link name="base_link">
    <inertial>
      <mass value="0.001"/>
      <inertia ixx="1.0e-06" ixy="0.0" ixz="0.0" iyy="1.0e-06" iyz="0.0" izz="1.0e-06"/>
    </inertial>
  </link>
  <gazebo>
    <plugin filename="libxbot2_gz_joint_server.so" name="xbot2_gz_joint_server">
      <pid>
        <gain d="10" name="small_mot" p="100"/>
        <gain d="50" name="medium_mot" p="500"/>
        <gain d="100" name="big_mot" p="1000"/>
        <gain name="J1_A" profile="medium_mot"/>
        <gain name="J2_A" profile="medium_mot"/>
        <gain name="J3_A" profile="medium_mot"/>
        <gain name="J4_A" profile="medium_mot"/>
        <gain name="J5_A" profile="medium_mot"/>
        <gain name="J6_A" profile="medium_mot"/>
      </pid>
    </plugin>
  </gazebo>
  <link name="L_0_A">
    <visual>
      <origin rpy="0.0 0.0 0.0" xyz="0.0 0.0 0.06"/>
      <geometry>
        <mesh filename="package://modular_resources/models/modular/meshes/alberobotics/module_base_mesh.stl" scale="0.001 0.001 0.001"/>
      </geometry>
      <material name="tree_green"/>
    </visual>
    <collision>
      <origin rpy="0.0 0.0 0.0" xyz="0.0 0.0 0.03"/>
      <geometry>
        <cylinder length="0.06" radius="0.045"/>
      </geometry>
    </collision>
    <inertial>
      <origin rpy="0 0 0" xyz="0.0 0.0 0.035"/>
      <mass value="0.76"/>
      <inertia ixx="0.005" ixy="5e-06" ixz="5e-06" iyy="0.005" iyz="5e-06" izz="0.002"/>
    </inertial>
  </link>
  <gazebo reference="L_0_A">
    <mu1>0.2</mu1>
    <mu2>0.2</mu2>
    <kp>1000000.0</kp>
    <kd>1.0</kd>
    <maxVel>0.0</maxVel>
    <minDepth>0.0001</minDepth>
    <material>Gazebo/Gray</material>
    <selfCollide>True</selfCollide>
  </gazebo>
  <joint name="L_0_A_fixed_joint_0" type="fixed">
    <axis rpy="0 0 0" xyz="0 0 1"/>
    <parent link="base_link"/>
    <child link="L_0_A"/>
    <origin rpy="0.0 -0.0 0.0" xyz="0.0 0.0 0.0"/>
  </joint>
  <joint name="fixed_J1_A" type="fixed">
    <axis rpy="0 0 0" xyz="0 0 1"/>
    <parent link="L_0_A"/>
    <child link="J1_A_stator"/>
    <origin rpy="0.0 -0.0 0.0" xyz="0.0 0.0 0.06"/>
  </joint>
  <link name="J1_A_stator">
    <visual>
      <origin rpy="0.0 0.0 0.0" xyz="0.0 0.0 0.0"/>
      <geometry>
        <mesh filename="package://modular_resources/models/modular/meshes/alberobotics/yaw_base.stl" scale="0.001 0.001 0.001"/>
      </geometry>
      <material name="tree_green"/>
    </visual>
    <collision>
      <origin rpy="0.0 0.0 0.0" xyz="0.0 0.0 0.0"/>
      <geometry>
        <mesh filename="package://modular_resources/models/modular/meshes/alberobotics/simple/yaw_base.stl" scale="0.001 0.001 0.001"/>
      </geometry>
    </collision>
    <inertial>
      <origin rpy="0 0 0" xyz="0.0 0.0 0.10614489"/>
      <mass value="2.0554934"/>
      <inertia ixx="0.01068855" ixy="-1.14168e-05" ixz="2.71689e-06" iyy="0.010584907" iyz="8.76312e-05" izz="0.0032026258"/>
    </inertial>
  </link>
  <gazebo reference="J1_A_stator">
    <mu1>0.2</mu1>
    <mu2>0.2</mu2>
    <kp>1000000.0</kp>
    <kd>1.0</kd>
    <maxVel>0.0</maxVel>
    <minDepth>0.0001</minDepth>
    <material>Gazebo/Blue</material>
    <selfCollide>True</selfCollide>
  </gazebo>
  <joint name="J1_A" type="revolute">
    <axis rpy="0 0 0" xyz="0 0 1"/>
    <parent link="J1_A_stator"/>
    <child link="L_1_A"/>
    <origin rpy="0.0 -0.0 0.0" xyz="0.0 0.0 0.214"/>
    <limit effort="147" lower="-2.8" upper="2.8" velocity="3.9"/>
  </joint>
  <link name="L_1_A">
    <visual>
      <origin rpy="0.0 0.0 0.0" xyz="0.0 0.0 0.0"/>
      <geometry>
        <mesh filename="package://modular_resources/models/modular/meshes/alberobotics/yaw_link.stl" scale="0.001 0.001 0.001"/>
      </geometry>
      <material name="tree_green"/>
    </visual>
    <collision>
      <origin rpy="0.0 0.0 0.0" xyz="0.0 0.0 0.0"/>
      <geometry>
        <mesh filename="package://modular_resources/models/modular/meshes/alberobotics/simple/yaw_link.stl" scale="0.001 0.001 0.001"/>
      </geometry>
    </collision>
    <inertial>
      <origin rpy="0 0 0" xyz="0.0 0.0 -0.024438213"/>
      <mass value="0.42322395"/>
      <inertia ixx="0.00063746146" ixy="1.1903424e-05" ixz="6.7230372e-07" iyy="0.00064218987" iyz="2.203073e-05" izz="0.001009674"/>
    </inertial>
  </link>
  <gazebo reference="L_1_A">
    <mu1>0.2</mu1>
    <mu2>0.2</mu2>
    <kp>1000000.0</kp>
    <kd>1.0</kd>
    <maxVel>0.0</maxVel>
    <minDepth>0.0001</minDepth>
    <material>Gazebo/White</material>
    <selfCollide>True</selfCollide>
  </gazebo>
  <joint name="fixed_L_1_A_rotor_fast" type="fixed">
    <axis rpy="0 0 0" xyz="0 0 1"/>
    <parent link="L_1_A"/>
    <child link="L_1_A_rotor_fast"/>
    <origin rpy="0.0 -0.0 0.0" xyz="0.0 0.0 0.0"/>
  </joint>
  <link name="L_1_A_rotor_fast">
    <inertial>
      <origin rpy="0 0 0" xyz="0.0 0.0 -0.0978986"/>
      <mass value="0.197124"/>
      <inertia ixx="0.00016128216" ixy="-2.4229e-07" ixz="3.771218e-06" iyy="0.00016138868" iyz="-2.4900687e-06" izz="0.12876379999999998"/>
    </inertial>
  </link>
  <joint name="fixed_J2_A" type="fixed">
    <axis rpy="0 0 0" xyz="0 0 1"/>
    <parent link="L_1_A"/>
    <child link="J2_A_stator"/>
    <origin rpy="0.0 -0.0 0.0" xyz="0.0 0.0 0.0"/>
  </joint>
  <link name="J2_A_stator">
    <visual>
      <origin rpy="0.0 0.0 0.0" xyz="0.0 0.0 0.0"/>
      <geometry>
        <mesh filename="package://modular_resources/models/modular/meshes/alberobotics/elbow_base.stl" scale="0.001 0.001 0.001"/>
      </geometry>
      <material name="tree_green"/>
    </visual>
    <collision>
      <origin rpy="0.0 0.0 0.0" xyz="0.0 0.0 0.0"/>
      <geometry>
        <mesh filename="package://modular_resources/models/modular/meshes/alberobotics/simple/elbow_base.stl" scale="0.001 0.001 0.001"/>
      </geometry>
    </collision>
    <inertial>
      <origin rpy="0 0 0" xyz="0.0 -0.013666345 0.095904755"/>
      <mass value="1.8627994"/>
      <inertia ixx="0.0080669105" ixy="6.8780537e-06" ixz="2.4976943e-05" iyy="0.0069731259" iyz="0.00033158425" izz="0.0037855995"/>
    </inertial>
  </link>
  <gazebo reference="J2_A_stator">
    <mu1>0.2</mu1>
    <mu2>0.2</mu2>
    <kp>1000000.0</kp>
    <kd>1.0</kd>
    <maxVel>0.0</maxVel>
    <minDepth>0.0001</minDepth>
    <material>Gazebo/Blue</material>
    <selfCollide>True</selfCollide>
  </gazebo>
  <joint name="J2_A" type="revolute">
    <axis rpy="0 0 0" xyz="0 0 1"/>
    <parent link="J2_A_stator"/>
    <child link="L_2_A"/>
    <origin rpy="-1.57 -0.0 0.0" xyz="0.0 0.07214997712353187 0.1320574549721794"/>
    <limit effort="147" lower="-2.0" upper="2.0" velocity="3.9"/>
  </joint>
  <link name="L_2_A">
    <visual>
      <origin rpy="0.0 3.14 0.0" xyz="0.0 0.0 -0.072"/>
      <geometry>
        <mesh filename="package://modular_resources/models/modular/meshes/alberobotics/elbow_link.stl" scale="0.001 0.001 0.001"/>
      </geometry>
      <material name="tree_green"/>
    </visual>
    <collision>
      <origin rpy="0.0 3.14 0.0" xyz="0.0 0.0 -0.072"/>
      <geometry>
        <mesh filename="package://modular_resources/models/modular/meshes/alberobotics/simple/elbow_link.stl" scale="0.001 0.001 0.001"/>
      </geometry>
    </collision>
    <inertial>
      <origin rpy="0 0 0" xyz="0.0 -0.040608854 -0.038467625"/>
      <mass value="1.1036463"/>
      <inertia ixx="0.0048243291" ixy="6.7819559e-06" ixz="-3.6661875e-06" iyy="0.0024139151" iyz="-0.0010484708" izz="0.0049751925"/>
    </inertial>
  </link>
  <gazebo reference="L_2_A">
    <mu1>0.2</mu1>
    <mu2>0.2</mu2>
    <kp>1000000.0</kp>
    <kd>1.0</kd>
    <maxVel>0.0</maxVel>
    <minDepth>0.0001</minDepth>
    <material>Gazebo/White</material>
    <selfCollide>True</selfCollide>
  </gazebo>
  <joint name="fixed_L_2_A_rotor_fast" type="fixed">
    <axis rpy="0 0 0" xyz="0 0 1"/>
    <parent link="L_2_A"/>
    <child link="L_2_A_rotor_fast"/>
    <origin rpy="0.0 -0.0 0.0" xyz="0.0 0.0 0.0"/>
  </joint>
  <link name="L_2_A_rotor_fast">
    <inertial>
      <origin rpy="0 0 0" xyz="0.0 0.0 -0.0978986"/>
      <mass value="0.197124"/>
      <inertia ixx="0.00016128216" ixy="-2.4229e-07" ixz="3.771218e-06" iyy="0.00016138868" iyz="-2.4900687e-06" izz="0.12876379999999998"/>
    </inertial>
  </link>
  <joint name="fixed_J3_A" type="fixed">
    <axis rpy="0 0 0" xyz="0 0 1"/>
    <parent link="L_2_A"/>
    <child link="J3_A_stator"/>
    <origin rpy="1.57 -0.0 0.0" xyz="0.0 -0.13199995814700216 -0.07204488487418322"/>
  </joint>
  <link name="J3_A_stator">
    <visual>
      <origin rpy="0.0 0.0 0.0" xyz="0.0 0.0 0.0"/>
      <geometry>
        <mesh filename="package://modular_resources/models/modular/meshes/alberobotics/yaw_base.stl" scale="0.001 0.001 0.001"/>
      </geometry>
      <material name="tree_green"/>
    </visual>
    <collision>
      <origin rpy="0.0 0.0 0.0" xyz="0.0 0.0 0.0"/>
      <geometry>
        <mesh filename="package://modular_resources/models/modular/meshes/alberobotics/simple/yaw_base.stl" scale="0.001 0.001 0.001"/>
      </geometry>
    </collision>
    <inertial>
      <origin rpy="0 0 0" xyz="0.0 0.0 0.10614489"/>
      <mass value="2.0554934"/>
      <inertia ixx="0.01068855" ixy="-1.14168e-05" ixz="2.71689e-06" iyy="0.010584907" iyz="8.76312e-05" izz="0.0032026258"/>
    </inertial>
  </link>
  <gazebo reference="J3_A_stator">
    <mu1>0.2</mu1>
    <mu2>0.2</mu2>
    <kp>1000000.0</kp>
    <kd>1.0</kd>
    <maxVel>0.0</maxVel>
    <minDepth>0.0001</minDepth>
    <material>Gazebo/Blue</material>
    <selfCollide>True</selfCollide>
  </gazebo>
  <joint name="J3_A" type="revolute">
    <axis rpy="0 0 0" xyz="0 0 1"/>
    <parent link="J3_A_stator"/>
    <child link="L_3_A"/>
    <origin rpy="0.0 -0.0 0.0" xyz="0.0 0.0 0.214"/>
    <limit effort="147" lower="-2.8" upper="2.8" velocity="3.9"/>
  </joint>
  <link name="L_3_A">
    <visual>
      <origin rpy="0.0 0.0 0.0" xyz="0.0 0.0 0.0"/>
      <geometry>
        <mesh filename="package://modular_resources/models/modular/meshes/alberobotics/yaw_link.stl" scale="0.001 0.001 0.001"/>
      </geometry>
      <material name="tree_green"/>
    </visual>
    <collision>
      <origin rpy="0.0 0.0 0.0" xyz="0.0 0.0 0.0"/>
      <geometry>
        <mesh filename="package://modular_resources/models/modular/meshes/alberobotics/simple/yaw_link.stl" scale="0.001 0.001 0.001"/>
      </geometry>
    </collision>
    <inertial>
      <origin rpy="0 0 0" xyz="0.0 0.0 -0.024438213"/>
      <mass value="0.42322395"/>
      <inertia ixx="0.00063746146" ixy="1.1903424e-05" ixz="6.7230372e-07" iyy="0.00064218987" iyz="2.203073e-05" izz="0.001009674"/>
    </inertial>
  </link>
  <gazebo reference="L_3_A">
    <mu1>0.2</mu1>
    <mu2>0.2</mu2>
    <kp>1000000.0</kp>
    <kd>1.0</kd>
    <maxVel>0.0</maxVel>
    <minDepth>0.0001</minDepth>
    <material>Gazebo/White</material>
    <selfCollide>True</selfCollide>
  </gazebo>
  <joint name="fixed_L_3_A_rotor_fast" type="fixed">
    <axis rpy="0 0 0" xyz="0 0 1"/>
    <parent link="L_3_A"/>
    <child link="L_3_A_rotor_fast"/>
    <origin rpy="0.0 -0.0 0.0" xyz="0.0 0.0 0.0"/>
  </joint>
  <link name="L_3_A_rotor_fast">
    <inertial>
      <origin rpy="0 0 0" xyz="0.0 0.0 -0.0978986"/>
      <mass value="0.197124"/>
      <inertia ixx="0.00016128216" ixy="-2.4229e-07" ixz="3.771218e-06" iyy="0.00016138868" iyz="-2.4900687e-06" izz="0.12876379999999998"/>
    </inertial>
  </link>
  <joint name="fixed_J4_A" type="fixed">
    <axis rpy="0 0 0" xyz="0 0 1"/>
    <parent link="L_3_A"/>
    <child link="J4_A_stator"/>
    <origin rpy="0.0 -0.0 0.0" xyz="0.0 0.0 0.0"/>
  </joint>
  <link name="J4_A_stator">
    <visual>
      <origin rpy="0.0 0.0 0.0" xyz="0.0 0.0 0.0"/>
      <geometry>
        <mesh filename="package://modular_resources/models/modular/meshes/alberobotics/elbow_base.stl" scale="0.001 0.001 0.001"/>
      </geometry>
      <material name="tree_green"/>
    </visual>
    <collision>
      <origin rpy="0.0 0.0 0.0" xyz="0.0 0.0 0.0"/>
      <geometry>
        <mesh filename="package://modular_resources/models/modular/meshes/alberobotics/simple/elbow_base.stl" scale="0.001 0.001 0.001"/>
      </geometry>
    </collision>
    <inertial>
      <origin rpy="0 0 0" xyz="0.0 -0.013666345 0.095904755"/>
      <mass value="1.8627994"/>
      <inertia ixx="0.0080669105" ixy="6.8780537e-06" ixz="2.4976943e-05" iyy="0.0069731259" iyz="0.00033158425" izz="0.0037855995"/>
    </inertial>
  </link>
  <gazebo reference="J4_A_stator">
    <mu1>0.2</mu1>
    <mu2>0.2</mu2>
    <kp>1000000.0</kp>
    <kd>1.0</kd>
    <maxVel>0.0</maxVel>
    <minDepth>0.0001</minDepth>
    <material>Gazebo/Blue</material>
    <selfCollide>True</selfCollide>
  </gazebo>
  <joint name="J4_A" type="revolute">
    <axis rpy="0 0 0" xyz="0 0 1"/>
    <parent link="J4_A_stator"/>
    <child link="L_4_A"/>
    <origin rpy="-1.57 -0.0 0.0" xyz="0.0 0.07214997712353187 0.1320574549721794"/>
    <limit effort="147" lower="-2.0" upper="2.0" velocity="3.9"/>
  </joint>
  <link name="L_4_A">
    <visual>
      <origin rpy="0.0 3.14 0.0" xyz="0.0 0.0 -0.072"/>
      <geometry>
        <mesh filename="package://modular_resources/models/modular/meshes/alberobotics/elbow_link.stl" scale="0.001 0.001 0.001"/>
      </geometry>
      <material name="tree_green"/>
    </visual>
    <collision>
      <origin rpy="0.0 3.14 0.0" xyz="0.0 0.0 -0.072"/>
      <geometry>
        <mesh filename="package://modular_resources/models/modular/meshes/alberobotics/simple/elbow_link.stl" scale="0.001 0.001 0.001"/>
      </geometry>
    </collision>
    <inertial>
      <origin rpy="0 0 0" xyz="0.0 -0.040608854 -0.038467625"/>
      <mass value="1.1036463"/>
      <inertia ixx="0.0048243291" ixy="6.7819559e-06" ixz="-3.6661875e-06" iyy="0.0024139151" iyz="-0.0010484708" izz="0.0049751925"/>
    </inertial>
  </link>
  <gazebo reference="L_4_A">
    <mu1>0.2</mu1>
    <mu2>0.2</mu2>
    <kp>1000000.0</kp>
    <kd>1.0</kd>
    <maxVel>0.0</maxVel>
    <minDepth>0.0001</minDepth>
    <material>Gazebo/White</material>
    <selfCollide>True</selfCollide>
  </gazebo>
  <joint name="fixed_L_4_A_rotor_fast" type="fixed">
    <axis rpy="0 0 0" xyz="0 0 1"/>
    <parent link="L_4_A"/>
    <child link="L_4_A_rotor_fast"/>
    <origin rpy="0.0 -0.0 0.0" xyz="0.0 0.0 0.0"/>
  </joint>
  <link name="L_4_A_rotor_fast">
    <inertial>
      <origin rpy="0 0 0" xyz="0.0 0.0 -0.0978986"/>
      <mass value="0.197124"/>
      <inertia ixx="0.00016128216" ixy="-2.4229e-07" ixz="3.771218e-06" iyy="0.00016138868" iyz="-2.4900687e-06" izz="0.12876379999999998"/>
    </inertial>
  </link>
  <joint name="fixed_J5_A" type="fixed">
    <axis rpy="0 0 0" xyz="0 0 1"/>
    <parent link="L_4_A"/>
    <child link="J5_A_stator"/>
    <origin rpy="1.57 -0.0 0.0" xyz="0.0 -0.13199995814700216 -0.07204488487418322"/>
  </joint>
  <link name="J5_A_stator">
    <visual>
      <origin rpy="0.0 0.0 0.0" xyz="0.0 0.0 0.0"/>
      <geometry>
        <mesh filename="package://modular_resources/models/modular/meshes/alberobotics/yaw_base.stl" scale="0.001 0.001 0.001"/>
      </geometry>
      <material name="tree_green"/>
    </visual>
    <collision>
      <origin rpy="0.0 0.0 0.0" xyz="0.0 0.0 0.0"/>
      <geometry>
        <mesh filename="package://modular_resources/models/modular/meshes/alberobotics/simple/yaw_base.stl" scale="0.001 0.001 0.001"/>
      </geometry>
    </collision>
    <inertial>
      <origin rpy="0 0 0" xyz="0.0 0.0 0.10614489"/>
      <mass value="2.0554934"/>
      <inertia ixx="0.01068855" ixy="-1.14168e-05" ixz="2.71689e-06" iyy="0.010584907" iyz="8.76312e-05" izz="0.0032026258"/>
    </inertial>
  </link>
  <gazebo reference="J5_A_stator">
    <mu1>0.2</mu1>
    <mu2>0.2</mu2>
    <kp>1000000.0</kp>
    <kd>1.0</kd>
    <maxVel>0.0</maxVel>
    <minDepth>0.0001</minDepth>
    <material>Gazebo/Blue</material>
    <selfCollide>True</selfCollide>
  </gazebo>
  <joint name="J5_A" type="revolute">
    <axis rpy="0 0 0" xyz="0 0 1"/>
    <parent link="J5_A_stator"/>
    <child link="L_5_A"/>
    <origin rpy="0.0 -0.0 0.0" xyz="0.0 0.0 0.214"/>
    <limit effort="147" lower="-2.8" upper="2.8" velocity="3.9"/>
  </joint>
  <link name="L_5_A">
    <visual>
      <origin rpy="0.0 0.0 0.0" xyz="0.0 0.0 0.0"/>
      <geometry>
        <mesh filename="package://modular_resources/models/modular/meshes/alberobotics/yaw_link.stl" scale="0.001 0.001 0.001"/>
      </geometry>
      <material name="tree_green"/>
    </visual>
    <collision>
      <origin rpy="0.0 0.0 0.0" xyz="0.0 0.0 0.0"/>
      <geometry>
        <mesh filename="package://modular_resources/models/modular/meshes/alberobotics/simple/yaw_link.stl" scale="0.001 0.001 0.001"/>
      </geometry>
    </collision>
    <inertial>
      <origin rpy="0 0 0" xyz="0.0 0.0 -0.024438213"/>
      <mass value="0.42322395"/>
      <inertia ixx="0.00063746146" ixy="1.1903424e-05" ixz="6.7230372e-07" iyy="0.00064218987" iyz="2.203073e-05" izz="0.001009674"/>
    </inertial>
  </link>
  <gazebo reference="L_5_A">
    <mu1>0.2</mu1>
    <mu2>0.2</mu2>
    <kp>1000000.0</kp>
    <kd>1.0</kd>
    <maxVel>0.0</maxVel>
    <minDepth>0.0001</minDepth>
    <material>Gazebo/White</material>
    <selfCollide>True</selfCollide>
  </gazebo>
  <joint name="fixed_L_5_A_rotor_fast" type="fixed">
    <axis rpy="0 0 0" xyz="0 0 1"/>
    <parent link="L_5_A"/>
    <child link="L_5_A_rotor_fast"/>
    <origin rpy="0.0 -0.0 0.0" xyz="0.0 0.0 0.0"/>
  </joint>
  <link name="L_5_A_rotor_fast">
    <inertial>
      <origin rpy="0 0 0" xyz="0.0 0.0 -0.0978986"/>
      <mass value="0.197124"/>
      <inertia ixx="0.00016128216" ixy="-2.4229e-07" ixz="3.771218e-06" iyy="0.00016138868" iyz="-2.4900687e-06" izz="0.12876379999999998"/>
    </inertial>
  </link>
  <joint name="fixed_J6_A" type="fixed">
    <axis rpy="0 0 0" xyz="0 0 1"/>
    <parent link="L_5_A"/>
    <child link="J6_A_stator"/>
    <origin rpy="0.0 -0.0 0.0" xyz="0.0 0.0 0.0"/>
  </joint>
  <link name="J6_A_stator">
    <visual>
      <origin rpy="0.0 0.0 0.0" xyz="0.0 0.0 0.0"/>
      <geometry>
        <mesh filename="package://modular_resources/models/modular/meshes/alberobotics/elbow_base.stl" scale="0.001 0.001 0.001"/>
      </geometry>
      <material name="tree_green"/>
    </visual>
    <collision>
      <origin rpy="0.0 0.0 0.0" xyz="0.0 0.0 0.0"/>
      <geometry>
        <mesh filename="package://modular_resources/models/modular/meshes/alberobotics/simple/elbow_base.stl" scale="0.001 0.001 0.001"/>
      </geometry>
    </collision>
    <inertial>
      <origin rpy="0 0 0" xyz="0.0 -0.013666345 0.095904755"/>
      <mass value="1.8627994"/>
      <inertia ixx="0.0080669105" ixy="6.8780537e-06" ixz="2.4976943e-05" iyy="0.0069731259" iyz="0.00033158425" izz="0.0037855995"/>
    </inertial>
  </link>
  <gazebo reference="J6_A_stator">
    <mu1>0.2</mu1>
    <mu2>0.2</mu2>
    <kp>1000000.0</kp>
    <kd>1.0</kd>
    <maxVel>0.0</maxVel>
    <minDepth>0.0001</minDepth>
    <material>Gazebo/Blue</material>
    <selfCollide>True</selfCollide>
  </gazebo>
  <joint name="J6_A" type="revolute">
    <axis rpy="0 0 0" xyz="0 0 1"/>
    <parent link="J6_A_stator"/>
    <child link="L_6_A"/>
    <origin rpy="-1.57 -0.0 0.0" xyz="0.0 0.07214997712353187 0.1320574549721794"/>
    <limit effort="147" lower="-2.0" upper="2.0" velocity="3.9"/>
  </joint>
  <link name="L_6_A">
    <visual>
      <origin rpy="0.0 3.14 0.0" xyz="0.0 0.0 -0.072"/>
      <geometry>
        <mesh filename="package://modular_resources/models/modular/meshes/alberobotics/elbow_link.stl" scale="0.001 0.001 0.001"/>
      </geometry>
      <material name="tree_green"/>
    </visual>
    <collision>
      <origin rpy="0.0 3.14 0.0" xyz="0.0 0.0 -0.072"/>
      <geometry>
        <mesh filename="package://modular_resources/models/modular/meshes/alberobotics/simple/elbow_link.stl" scale="0.001 0.001 0.001"/>
      </geometry>
    </collision>
    <inertial>
      <origin rpy="0 0 0" xyz="0.0 -0.040608854 -0.038467625"/>
      <mass value="1.1036463"/>
      <inertia ixx="0.0048243291" ixy="6.7819559e-06" ixz="-3.6661875e-06" iyy="0.0024139151" iyz="-0.0010484708" izz="0.0049751925"/>
    </inertial>
  </link>
  <gazebo reference="L_6_A">
    <mu1>0.2</mu1>
    <mu2>0.2</mu2>
    <kp>1000000.0</kp>
    <kd>1.0</kd>
    <maxVel>0.0</maxVel>
    <minDepth>0.0001</minDepth>
    <material>Gazebo/White</material>
    <selfCollide>True</selfCollide>
  </gazebo>
  <joint name="fixed_L_6_A_rotor_fast" type="fixed">
    <axis rpy="0 0 0" xyz="0 0 1"/>
    <parent link="L_6_A"/>
    <child link="L_6_A_rotor_fast"/>
    <origin rpy="0.0 -0.0 0.0" xyz="0.0 0.0 0.0"/>
  </joint>
  <link name="L_6_A_rotor_fast">
    <inertial>
      <origin rpy="0 0 0" xyz="0.0 0.0 -0.0978986"/>
      <mass value="0.197124"/>
      <inertia ixx="0.00016128216" ixy="-2.4229e-07" ixz="3.771218e-06" iyy="0.00016138868" iyz="-2.4900687e-06" izz="0.12876379999999998"/>
    </inertial>
  </link>
  <link name="ee_A">
    <visual>
      <origin rpy="0 0 0" xyz="0 0 -0.0945"/>
      <geometry>
        <cylinder length="0.189" radius="0.02"/>
      </geometry>
      <material name="blue"/>
    </visual>
    <collision>
      <origin rpy="0 0 0" xyz="0 0 -0.0945"/>
      <geometry>
        <cylinder length="0.189" radius="0.02"/>
      </geometry>
    </collision>
    <inertial>
      <origin rpy="0 0 0" xyz="0 0 0.0945"/>
      <mass value="1.0"/>
      <inertia ixx="0.00307675" ixy="0.0" ixz="0.0" iyy="0.00307675" iyz="0.0" izz="0.0002"/>
    </inertial>
  </link>
  <joint name="L_6_fixed_joint_1_A" type="fixed">
    <axis rpy="0 0 0" xyz="0 0 1"/>
    <parent link="L_6_A"/>
    <child link="ee_A"/>
    <origin rpy="1.57 -0.0 0.0" xyz="0.0 -0.3209998982211189 -0.07189437912585463"/>
  </joint>
</robot>

